Workbook

Sheet Инвестору
B2: Общие условия | G2: Результаты
B4: Вложения инвестора | C4: 10000000 | G4: Окупаемость | J4: =MIN(26:26) -> 15 | K4: месяцев
B5: Доля инвестора | C5: 0.7 | D5: до окупаемости | G5: Доход за 1 год | I5: =-SUM(F24:N24) -> 6206332.5 | K5: рублей
C6: 0.5 | D6: после окупаемости | G6: Доход за 2 год | I6: =-SUM(O24:Z24) -> 14485502 | K6: рублей
B7: Открываем точек | C7: 10 | G7: Доход за 3 год | I7: =-SUM(AA24:AL24) -> 15148250 | K7: рублей
B8: Расходы на УК в месяц, рублей | C8: 750000 | G8: Итого за 3 года | I8: =SUM(I5:J7) -> 35840085 | K8: рублей
G9: ROI за 3 года | J9: =(I8-C4)/C4 -> 2.5840085
B11: Отчет о движении денег
B13: Месяц | C13: 1 | D13: 2 | E13: 3 | F13: 4 | G13: 5 | H13: 6 | I13: 7 | J13: 8 | K13: 9 | L13: 10 | M13: 11 | N13: 12 | O13: 13 | P13: 14 | Q13: 15 | R13: 16 | S13: 17 | T13: 18 | U13: 19 | V13: 20 | W13: 21 | X13: 22 | Y13: 23 | Z13: 24 | AA13: 25 | AB13: 26 | AC13: 27 | AD13: 28 | AE13: 29 | AF13: 30 | AG13: 31 | AH13: 32 | AI13: 33 | AJ13: 34 | AK13: 35 | AL13: 36
B14: Остаток денег на начало месяца | C14: 0 | D14: =C20 -> 1240000 | E14: =D20 -> 490000 | F14: =E20 -> 70561.333 | G14: =F20 -> -48027.333 | H14: =G20 -> 144101.88 | I14: =H20 -> 288179.33 | J14: =I20 -> 779831.19 | K14: =J20 -> 1462649 | ... AL14: =AK20 -> 44134605
B15: Операционная прибыль с точек [1] | E15: =Инвестору!J78*$C$7 -> 330561.33 | F15: =Инвестору!K78*$C$7 -> 631411.33 | G15: =Инвестору!L78*$C$7 -> 942129.21 | H15: =Инвестору!M78*$C$7 -> 894077.45 | I15: =Инвестору!N78*$C$7 -> 1241651.9 | J15: =Инвестору!O78*$C$7 -> 1432817.8 | K15: =Инвестору!P78*$C$7 -> 1633542 | L15: =Инвестору!Q78*$C$7 -> 1759998.3 | ... O15: =Инвестору!T78*$C$7 -> 2162587.8 | P15: =O15*101% -> 2184213.7 | Q15: =P15*101% -> 2206055.9 | R15: =Q15*101% -> 2228116.4 | S15: =R15*101% -> 2250397.6 | T15: =S15*101% -> 2272901.6 | U15: =T15*101% -> 2295630.6 | V15: =U15*101% -> 2318586.9 | W15: =V15*101% -> 2341772.7 | ... AL15: =AK15*101% -> 2718725.5
B16: Входящие инвестиции | C16: =C4 -> 10000000
B17: Вложения в открытие 10 точек | C17: =-Инвестору!E78*10 -> -8010000
B18: Расходы на УК | C18: =-$C$8 -> -750000 | D18: =-$C$8 -> -750000 | E18: =-$C$8 -> -750000 | F18: =-$C$8 -> -750000 | G18: =-$C$8 -> -750000 | H18: =-$C$8 -> -750000 | I18: =-$C$8 -> -750000 | J18: =-$C$8 -> -750000 | ... AL18: =-$C$8 -> -750000
B19: Возврат средств инвестору [2] | F19: =IF(E25>$C$4,-D15*$C$6,-D15*$C$5) -> 0 | G19: =IF(F25>$C$4,-E15*$C$6,-E15*$C$5) -> -231392.93 | H19: =IF(G25>$C$4,-F15*$C$6,-F15*$C$5) -> -441987.93 | I19: =IF(H25>$C$4,-G15*$C$6,-G15*$C$5) -> -659490.45 | J19: =IF(I25>$C$4,-H15*$C$6,-H15*$C$5) -> -625854.22 | K19: =IF(J25>$C$4,-I15*$C$6,-I15*$C$5) -> -869156.3 | L19: =IF(K25>$C$4,-J15*$C$6,-J15*$C$5) -> -1002972.5 | M19: =IF(L25>$C$4,-K15*$C$6,-K15*$C$5) -> -1143479.4 | ... AL19: =IF(AK25>$C$4,-AJ15*$C$6,-AJ15*$C$5) -> -1332577.9
B20: Остаток денег на конец месяца | C20: =SUM(C14:C18) -> 1240000 | D20: =SUM(D14:D18) -> 490000 | E20: =SUM(E14:E18) -> 70561.333 | F20: =SUM(F14:F18) -> -48027.333 | G20: =SUM(G14:G18) -> 144101.88 | H20: =SUM(H14:H18) -> 288179.33 | I20: =SUM(I14:I18) -> 779831.19 | J20: =SUM(J14:J18) -> 1462649 | ... AL20: =SUM(AL14:AL18) -> 46103330
B22: Инвестору
B23: Вложения | C23: =C16 -> 10000000
B24: Возврат средств | D24: =D19 -> 0 | E24: =E19 -> 0 | F24: =F19 -> 0 | G24: =G19 -> -231392.93 | H24: =H19 -> -441987.93 | I24: =I19 -> -659490.45 | J24: =J19 -> -625854.22 | K24: =K19 -> -869156.3 | ... AL24: =AL19 -> -1332577.9
B25: Возврат накопительно | E25: =D25-E24 -> 0 | F25: =E25-F24 -> 0 | G25: =F25-G24 -> 231392.93 | H25: =G25-H24 -> 673380.87 | I25: =H25-I24 -> 1332871.3 | J25: =I25-J24 -> 1958725.5 | K25: =J25-K24 -> 2827881.8 | L25: =K25-L24 -> 3830854.3 | ... AL25: =AK25-AL24 -> 35840085
B26: Окупаемость | E26: =IF(E25>$C$23,E13,"") | F26: =IF(F25>$C$23,F13,"") | G26: =IF(G25>$C$23,G13,"") | H26: =IF(H25>$C$23,H13,"") | I26: =IF(I25>$C$23,I13,"") | J26: =IF(J25>$C$23,J13,"") | K26: =IF(K25>$C$23,K13,"") | L26: =IF(L25>$C$23,L13,"") | ... AL26: =IF(AL25>$C$23,AL13,"") -> 36
B28: [1] для расчета используется «чистая прибыль» с вкладки «финплан 1 точка»
B29: Точки работают с 3-го месяца. Мы рассчитываем 2 месяца с запасом на поиск локаций, подготовку.
B30: После 12 места заложен рост прибыли 1% в месяц
B31: Рост продаж в первые 3 месяца для точки взят пессимистичный — 10% вместо 20% в базовом прогнозе
B33: [2] выплата доли средств инвестору выполняется через месяц, в котором получена прибыль
B34: Для того, чтобы не попадать в кассовый разрыв в момент роста
H41: Месяц | I41: 1 | J41: 2 | K41: 3 | L41: 4 | M41: 5 | N41: 6 | O41: 7 | P41: 8 | Q41: 9 | R41: 10 | S41: 11 | T41: 12
B43: ПОКАЗАТЕЛИ | H43: ВЫРУЧКА | I43: =I45 -> 0 | J43: =J45 -> 601700 | K43: =K45 -> 661870 | L43: =L45 -> 728057 | M43: =M45 -> 800862.7 | N43: =N45 -> 880948.97 | O43: =O45 -> 924996.42 | P43: =P45 -> 971246.24 | ... T43: =T45 -> 1093146.2
B45: Точка безубыточности (руб/мес) | E45: =(T63+T75+T76)/E50 -> 660628.63 | H45: Выручка от продаж | J45: =J46*J47 -> 601700 | K45: =K46*K47 -> 661870 | L45: =L46*L47 -> 728057 | M45: =M46*M47 -> 800862.7 | N45: =N46*N47 -> 880948.97 | O45: =O46*O47 -> 924996.42 | P45: =P46*P47 -> 971246.24 | Q45: =Q46*Q47 -> 1000383.6 | ... T45: =T46*T47 -> 1093146.2
B46: Точка безубыточности (руб/день) | E46: =E45/T46 -> 30028.574 | H46: Кол-во рабочих дней | J46: 22 | K46: =J46 -> 22 | L46: =K46 -> 22 | M46: =L46 -> 22 | N46: =M46 -> 22 | O46: =N46 -> 22 | P46: =O46 -> 22 | Q46: =P46 -> 22 | R46: =Q46 -> 22 | ... T46: =S46 -> 22
H47: Выручка в день | J47: =SUMPRODUCT($G$51:$G$58,J51:J58) -> 27350 | K47: =SUMPRODUCT($G$51:$G$58,K51:K58) -> 30085 | L47: =SUMPRODUCT($G$51:$G$58,L51:L58) -> 33093.5 | M47: =SUMPRODUCT($G$51:$G$58,M51:M58) -> 36402.85 | N47: =SUMPRODUCT($G$51:$G$58,N51:N58) -> 40043.135 | O47: =SUMPRODUCT($G$51:$G$58,O51:O58) -> 42045.292 | P47: =SUMPRODUCT($G$51:$G$58,P51:P58) -> 44147.556 | Q47: =SUMPRODUCT($G$51:$G$58,Q51:Q58) -> 45471.983 | ... T47: =SUMPRODUCT($G$51:$G$58,T51:T58) -> 49688.464
H48: Чеков в день (ср чек 220р) | J48: =J47/220 -> 124.31818 | K48: =K47/220 -> 136.75 | L48: =L47/220 -> 150.425 | M48: =M47/220 -> 165.4675 | N48: =N47/220 -> 182.01425 | O48: =O47/220 -> 191.11496 | P48: =P47/220 -> 200.67071 | Q48: =Q47/220 -> 206.69083 | ... T48: =T47/220 -> 225.85665
G49: 0.1 | H49: Рост продаж в месяц | K49: =G49 -> 0.1 | L49: =K49 -> 0.1 | M49: =L49 -> 0.1 | N49: =M49 -> 0.1 | O49: 0.05 | P49: =O49 -> 0.05 | Q49: 0.03 | R49: =Q49 -> 0.03 | S49: =R49 -> 0.03 | T49: =S49 -> 0.03
B50: Маржинальность средняя | E50: =T61/T45 -> 0.5 | G50: Цена | H50: Наименование
G51: 100 | H51: КОФЕ | J51: 50 | K51: =J51*(100%+K$49) -> 55 | L51: =K51*(100%+L$49) -> 60.5 | M51: =L51*(100%+M$49) -> 66.55 | N51: =M51*(100%+N$49) -> 73.205 | O51: =N51*(100%+O$49) -> 76.86525 | P51: =O51*(100%+P$49) -> 80.708513 | Q51: =P51*(100%+Q$49) -> 83.129768 | R51: =Q51*(100%+R$49) -> 85.623661 | ... T51: =S51*(100%+T$49) -> 90.838142
B52: Итого вложения всего (с запасом): | E52: =E78 -> 801000 | G52: 180 | H52: ВТОРЫЕ БЛЮДА | J52: 70 | K52: =J52*(100%+K$49) -> 77 | L52: =K52*(100%+L$49) -> 84.7 | M52: =L52*(100%+M$49) -> 93.17 | N52: =M52*(100%+N$49) -> 102.487 | O52: =N52*(100%+O$49) -> 107.61135 | P52: =O52*(100%+P$49) -> 112.99192 | Q52: =P52*(100%+Q$49) -> 116.38168 | R52: =Q52*(100%+R$49) -> 119.87313 | ... T52: =S52*(100%+T$49) -> 127.1734
B53: Месяц окупаемости | E53: =MIN(I82:T82) -> 9 | G53: 120 | H53: ПЕРВЫЕ БЛЮДА | J53: 5 | K53: =J53*(100%+K$49) -> 5.5 | L53: =K53*(100%+L$49) -> 6.05 | M53: =L53*(100%+M$49) -> 6.655 | N53: =M53*(100%+N$49) -> 7.3205 | O53: =N53*(100%+O$49) -> 7.686525 | P53: =O53*(100%+P$49) -> 8.0708513 | Q53: =P53*(100%+Q$49) -> 8.3129768 | R53: =Q53*(100%+R$49) -> 8.5623661 | ... T53: =S53*(100%+T$49) -> 9.0838142
G54: 120 | H54: САЛАТЫ | J54: 5 | K54: =J54*(100%+K$49) -> 5.5 | L54: =K54*(100%+L$49) -> 6.05 | M54: =L54*(100%+M$49) -> 6.655 | N54: =M54*(100%+N$49) -> 7.3205 | O54: =N54*(100%+O$49) -> 7.686525 | P54: =O54*(100%+P$49) -> 8.0708513 | Q54: =P54*(100%+Q$49) -> 8.3129768 | R54: =Q54*(100%+R$49) -> 8.5623661 | ... T54: =S54*(100%+T$49) -> 9.0838142
G55: 120 | H55: ДЕСЕРТЫ/ЗАВТРАКИ | J55: 10 | K55: =J55*(100%+K$49) -> 11 | L55: =K55*(100%+L$49) -> 12.1 | M55: =L55*(100%+M$49) -> 13.31 | N55: =M55*(100%+N$49) -> 14.641 | O55: =N55*(100%+O$49) -> 15.37305 | P55: =O55*(100%+P$49) -> 16.141703 | Q55: =P55*(100%+Q$49) -> 16.625954 | R55: =Q55*(100%+R$49) -> 17.124732 | ... T55: =S55*(100%+T$49) -> 18.167628
...
