Workbook

Sheet Диапазон
A1: Сентряборь | C1: Сентябрь | D1: 9 | F1: Тип оплаты
A2: 45170 | C2: Октябрь | D2: 10 | F2: A | G2: полная оплата
A3: 45171 | C3: Ноябрь | D3: 11 | F3: B | G3: оплата по внутренней рассрочке
A4: 45172 | C4: Декабрь | D4: 12 | F4: C | G4: оплата по рассрочке от Сбера
A5: 45173
A6: 45174
A7: 45175
A8: 45176
A9: 45177
A10: 45178
A11: 45179
A12: 45180
A13: 45181
A14: 45182
A15: 45183
A16: 45184
... A123: 45291

Sheet Sales PnL(архив)
A1: Воронка ВУ | H1: пересобрать тк -1день
B2: W35 | C2: 45170 | D2: W35 | E2: W36 | F2: W37 | G2: W38 | H2: W39 | I2: PtoF | J2: 45170 | K2: 45200 | L2: W39 | M2: W40 | N2: W41 | O2: W42 | P2: W43 | Q2: W44 | R2: PtoF | S2: 45200 | T2: 45231 | U2: W44 | V2: W45 | W2: W46 | X2: W47 | Y2: W48 | Z2: PtoF | AA2: 45231 | AB2: 45261 | AC2: W48 | AD2: W49 | AE2: W50 | AF2: W51 | AG2: W52 | AH2: PtoF | AI2: 45261
B3: 28.08-03.09 | C3: Факт | D3: 01.09-03.09 | E3: 04.09-10.09 | F3: 11.09-17.09 | G3: 18.09-24.09 | H3: 25.09-30.09 | J3: План | K3: Факт | L3: 45200 | M3: 2.10-8.10 | N3: 09.10-15.10 | O3: 16.10-22.10 | P3: 23.10-29.10 | Q3: 30.10-31.10 | S3: План | T3: Факт | U3: 1.11-5.11 | V3: 6.11-12.11 | W3: 13.11-19.11 | X3: 20.11-26.11 | Y3: 27.11-30.11 | AA3: План | AB3: Факт | AC3: 1.12-3.12 | AD3: 4.12-10.12 | AI3: План
A4: N, Total | C4: 0 | I4: =C4/J4 | J4: 36 | K4: =SUM(L4:P4) | L4: 0 | M4: 1 | N4: 0 | R4: =K4/S4 | S4: 45 | T4: =SUM(U4:Y4) | Z4: =T4/AA4 | AA4: 29 | AB4: =SUM(AC4:AG4) | AH4: =AA4/AI4 | AI4: 48
A5: Заявки новые | B5: 2 | C5: =D5+E5+F5+G5+H5 | D5: 4 | E5: 53 | F5: 25 | G5: 45 | H5: 19 | I5: =C5/J5 | J5: ='Marketing PnL'!R8 | K5: =M5+N5+O5+P5+Q5 | M5: 29 | N5: 65 | O5: 92 | P5: 153 | Q5: 50 | R5: =K5/S5 | S5: ='Marketing PnL'!AA8 | T5: =SUM(U5:Y5) | U5: 146 | V5: 162 | W5: 146 | X5: 222 | Y5: 124 | Z5: =T5/AA5 | AA5: 495 | AB5: =SUM(AC5:AG5) | AC5: 87 | AH5: =AA5/AI5 | AI5: 606
A6: CR дозвона
A7: Неквал | C7: =D7+E7+F7+G7+H7 | D7: 2 | E7: 44 | F7: 21 | G7: 30 | H7: 9 | I7: =C7/J7 | J7: =J5*J8 | K7: =M7+N7+O7+P7+Q7 | M7: 19 | N7: 38 | O7: 50 | P7: =P5-27 | Q7: =Q5-13 | R7: =K7/S7 | S7: =S5*S8 | T7: =SUM(U7:Y7) | U7: 67 | V7: 73 | W7: 60 | X7: 98 | Y7: 42 | Z7: =T7/AA7 | AA7: 371 | AB7: =SUM(AC7:AG7) | AC7: 16 | AH7: =AC7/AI7 | AI7: =AI5*AI8
A8: Количество Неквал | B8: =B7/B5 | C8: =C7/C5 | D8: =D7/D5 | E8: =E7/E5 | F8: =F7/F5 | G8: =G7/G5 | H8: =H7/H5 | I8: =C8/J8 | J8: 0.75 | K8: =K7/K5 | L8: =L7/L5 | M8: =M7/M5 | N8: =N7/N5 | O8: =O7/O5 | P8: =P7/P5 | Q8: =Q7/Q5 | R8: =K8/S8 | S8: 0.75 | T8: =T7/T5 | U8: =U7/U5 | V8: =V7/V5 | W8: =W7/W5 | X8: =X7/X5 | Y8: =Y7/Y5 | Z8: =T8/AA8 | AA8: 0.75 | AB8: =AB7/AB5 | AC8: =AC7/AC5 | AD8: =AD7/AD5 | AE8: =AE7/AE5 | AF8: =AF7/AF5 | AG8: =AG7/AG5 | AH8: =AC8/AI8 | AI8: 0.75
A9: ВУ назначено | C9: =D9+E9+F9+G9+H9 | D9: 1 | E9: 19 | F9: 13 | G9: 13 | H9: 12 | I9: =C9/J9 | J9: =J7*J10 | K9: =M9+N9+O9+P9+Q9 | M9: 12 | N9: 33 | O9: 42 | P9: 70 | Q9: 13 | R9: =K9/S9 | S9: =S7*S10 | T9: =SUM(U9:Y9) | U9: 29 | V9: 69 | W9: 43 | X9: 49 | Y9: 38 | Z9: =T9/AA9 | AA9: 260 | AB9: =SUM(AC9:AG9) | AC9: 16 | AH9: =AC9/AI9 | AI9: =AI7*AI10
A10: CR лид - ВУ назначено | B10: =B9/B7 | C10: =C9/C7 | D10: =D9/D7 | E10: =E9/E7 | F10: =F9/F7 | G10: =G9/G7 | H10: =H9/H7 | I10: =C10/J10 | J10: 0.7 | K10: =K9/K7 | L10: =L9/L7 | M10: =M9/M7 | N10: =N9/N7 | O10: =O9/O7 | P10: =P9/P7 | Q10: =Q9/Q7 | R10: =K10/S10 | S10: 0.7 | T10: =T9/(T5-T7) | U10: =U9/(U5-U7) | V10: =V9/(V5-V7) | W10: =W9/(W5-W7) | X10: =X9/(X5-X7) | Y10: =Y9/(Y5-Y7) | Z10: =T10/AA10 | AA10: 0.7 | AB10: =AB9/(AB5-AB7) | AC10: =AC9/AC7 | AD10: =AD9/AD7 | AE10: =AE9/AE7 | AF10: =AF9/AF7 | AG10: =AG9/AG7 | AH10: =AC10/AI10 | AI10: 0.7
A11: Время до ВУ | AH11: =AC11/AI11
A12: ВУ проведено | C12: =D12+E12+F12+G12+H12 | D12: 0 | E12: 8 | F12: 11 | G12: 1 | H12: 9 | I12: =C12/J12 | J12: =J9*J13 | K12: =M12+N12+O12+P12+Q12 | M12: 6 | N12: 6 | O12: 21 | P12: 22 | Q12: 4 | R12: =K12/S12 | S12: =S9*S13 | T12: =SUM(U12:Y12) | U12: 9 | V12: 22 | W12: 16 | X12: 19 | Y12: 12 | Z12: =T12/AA12 | AA12: 130 | AB12: =SUM(AC12:AG12) | AC12: 2 | AH12: =AC12/AI12 | AI12: =AI9*AI13
A13: CR ВУ назначено - ВУ проведено | B13: =B12/B9 | C13: =C12/C9 | D13: =D12/D9 | E13: =E12/E9 | F13: =F12/F9 | G13: =G12/G9 | H13: =H12/H9 | I13: =C13/J13 | J13: 0.4 | K13: =K12/K9 | L13: =L12/L9 | M13: =M12/M9 | N13: =N12/N9 | O13: =O12/O9 | P13: =P12/P9 | Q13: =Q12/Q9 | R13: =K13/S13 | S13: 0.45 | T13: =T12/T9 | U13: =U12/U9 | V13: =V12/V9 | W13: =W12/W9 | X13: =X12/X9 | Y13: =Y12/Y9 | Z13: =T13/AA13 | AA13: 0.5 | AB13: =AB12/AB9 | AC13: =AC12/AC9 | AD13: =AD12/AD9 | AE13: =AE12/AE9 | AF13: =AF12/AF9 | AG13: =AG12/AG9 | AH13: =AC13/AI13 | AI13: 0.5
A14: CR заявка- ВУ проведено | K14: =K12/K5 | M14: =M12/M5 | N14: =N12/N5 | O14: =O12/O5 | P14: =P12/P5 | Q14: =Q12/Q5 | S14: =S12/S5 | T14: =T12/T5 | U14: =U12/U5 | V14: =V12/V5 | W14: =W12/W5 | X14: =X12/X5 | Y14: =Y12/Y5 | AA14: =AA12/AA5 | AB14: =AB12/AB5 | AC14: =AC12/AC5 | AD14: =AD12/AD5 | AE14: =AE12/AE5 | AF14: =AF12/AF5 | AG14: =AG12/AG5 | AH14: =AC14/AI14 | AI14: =AI12/AI5
A15: Покупок | C15: =D15+E15+F15+G15+H15 | D15: 0 | E15: 2 | F15: 4 | G15: 0 | H15: 0 | I15: =C15/J15 | J15: =J12*J16 | K15: =M15+N15+O15+P15+Q15 | M15: 1 | N15: 0 | O15: 1 | P15: 2 | R15: =K15/S15 | S15: =S12*S16 | T15: =SUM(U15:Y15) | U15: 3 | V15: 2 | W15: 0 | X15: 1 | Y15: 0 | Z15: =T15/AA15 | AA15: =AA12*AA16 | AB15: =SUM(AC15:AG15) | AH15: =AC15/AI15 | AI15: =AI12*AI16
A16: CR ВУ - покупка | C16: =C15/C12 | D16: =D15/D12 | E16: =E15/E12 | F16: =F15/F12 | G16: =G15/G12 | H16: =H15/H12 | I16: =C16/J16 | J16: 0.4 | K16: =K15/K12 | M16: =M15/M12 | N16: =N15/N12 | O16: =O15/O12 | P16: =P15/P12 | Q16: =Q15/Q12 | R16: =K16/S16 | S16: 0.4 | T16: =T15/T12 | U16: =U15/U12 | V16: =V15/V12 | W16: =W15/W12 | X16: =X15/X12 | Y16: =Y15/Y12 | Z16: =T16/AA16 | AA16: 0.3 | AB16: =AB15/AB12 | AC16: =AC15/AC12 | AD16: =AD15/AD12 | AE16: =AE15/AE12 | AF16: =AF15/AF12 | AG16: =AG15/AG12 | AH16: =AC16/AI16 | AI16: 0.3
A17: ВУ - Оплата (окно 3 дня) | AH17: =AC17/AI17
A18: CR заявка - оплата | C18: =C15/C5 | E18: =E15/E5 | F18: =F15/F5 | G18: =G15/G5 | H18: =H15/H5 | I18: =C18/J18 | J18: 0.21 | K18: =K15/K5 | M18: =M15/M5 | N18: =N15/N5 | O18: =O15/O5 | P18: =P15/P5 | Q18: =Q15/Q5 | R18: =K18/S18 | S18: =S15/S5 | T18: =T15/T5 | U18: =U15/U5 | V18: =V15/V5 | W18: =W15/W5 | X18: =X15/X5 | Y18: =Y15/Y5 | Z18: =T18/AA18 | AA18: =AA15/AA5 | AB18: =AB15/AB5 | AC18: =AC15/AC5 | AD18: =AD15/AD5 | AE18: =AE15/AE5 | AF18: =AF15/AF5 | AG18: =AG15/AG5 | AH18: =AC18/AI18 | AI18: =AI15/AI5
A19: CR квал - проведено | C19: =C12/C7 | D19: =D12/D7 | E19: =E12/E7 | F19: =F12/F7 | G19: =G12/G7 | H19: =H12/H7 | I19: =C19/J19 | J19: =J12/J7 | K19: =K12/K7 | M19: =M12/M7 | N19: =N12/N7 | O19: =O12/O7 | P19: =P12/P7 | Q19: =Q12/Q7 | R19: =R12/R7 | S19: =S12/S7 | T19: =T12/T7 | ... AG19: =AG12/AG7 | AH19: =AC19/AI19 | AI19: =AI12/AI7
A20: Показатели продаж | AH20: =AC20/AI20
A21: Выручка | C21: =SUM(E21:H21) | E21: 84500 | F21: =18500*F15 | J21: 2376000 | K21: =L21+M21+N21+O21+P21 | M21: 18500 | O21: 74000 | P21: =74000+17353 | S21: 1545750 | T21: =U21+V21+W21+X21+Y21 | U21: =18500+66000+62000 | V21: =54000+74000 | X21: 62000 | AA21: 1609500 | AB21: =AC21+AD21+AE21+AF21+AG21 | AI21: 3008998
A22: Средний чек | C22: =C21/C15 | E22: =E21/E15 | F22: =F21/F15 | J22: =J21/J15 | M22: =M21/M15 | O22: =O21/O15 | P22: =P21/P15 | S22: =S21/S15 | T22: =AVERAGE(U22:Y22) | U22: =U21/U15 | V22: =V21/V15 | X22: =X21/X15 | AA22: 62100 | AC22: =AC21/AC15 | AD22: =AD21/AD15 | AF22: =AF21/AF15 | AG22: =AG21/AG15 | AI22: 62100
A23: CR заявка-назначено | K23: =K9/K5 | L23: =L9/L5 | M23: =M9/M5 | N23: =N9/N5 | O23: =O9/O5 | P23: =P9/P5 | R23: =R9/R5 | S23: =S9/S5 | T23: =T9/T5 | U23: =U9/U5 | V23: =V9/V5 | W23: =W9/W5 | X23: =X9/X5 | Y23: =Y9/Y5 | ... AI23: =AI9/AI5
Q25: =Q5+U5
Q26: =Q7+U7
A27: Воронка мини-курс | Q27: =Q9+U9+U34 | T27: 45231 | U27: мини курс | V27: W45 | W27: W46 | X27: W47 | Y27: W48 | Z27: PtoF | AA27: 45231
Q28: =Q27/Q26 | T28: Факт | U28: 30.10-5.11 | V28: 6.11-12.11 | W28: 13.11-19.11 | X28: 20.11-26.11 | Y28: 27.11-30.11 | AA28: План
A29: N, Total | P29: заявка-назначено | Q29: =Q27/Q25 | T29: =SUM(U29:Y29) | Z29: =T29/AA29 | AA29: 26
A30: Заявки новые | Q30: 13 | T30: =V30+W30+X30 | U30: 94 | Z30: =T30/AA30 | AA30: ='Marketing PnL'!AL34
A31: CR дозвона | Q31: 3
A32: Квалифицирован | P32: ВУ- покупка | Q32: =Q31/Q30 | T32: =V32+W32+X32 | U32: =U30-18 | Z32: =T32/AA32 | AA32: =AA30*AA33
A33: CR заявка-квалифицирован | T33: =T32/T30 | U33: =U32/U30 | V33: =V32/V30 | W33: =W32/W30 | X33: =X32/X30 | Y33: =Y32/Y30 | Z33: =T33/AA33 | AA33: 0.75
A34: мини-курс записан | T34: =V34+W34+X34 | U34: 35 | Z34: =T34/AA34 | AA34: =AA32*AA35
A35: CR квал лид - ВУ назначено | T35: =T34/T32 | U35: =U34/U32 | V35: =V34/V32 | W35: =W34/W32 | X35: =X34/X32 | Y35: =Y34/Y32 | Z35: =T35/AA35 | AA35: 0.7
A36: Время до ВУ
A37: мини-курс прошли курс | T37: =V37+W37+X37 | Z37: =T37/AA37 | AA37: =AA34*AA38
A38: CR ВУ назначено - ВУ проведено | T38: =T37/T34 | U38: =U37/U34 | V38: =V37/V34 | W38: =W37/W34 | X38: =X37/X34 | Y38: =Y37/Y34 | Z38: =T38/AA38 | AA38: 0.45
A39: CR заявка- ВУ проведено | E39: Олег З | G39: план | H39: факт | T39: =T37/T30 | U39: =U37/U30 | V39: =V37/V30 | W39: =W37/W30 | X39: =X37/X30 | Y39: =Y37/Y30 | AA39: =AA37/AA30
A40: Покупок | E40: состоялось ВУ | F40: 28 | T40: =V40+W40+X40+Y40 | Z40: =T40/AA40 | AA40: =AA37*AA41
A41: CR ВУ - покупка | E41: оплат | F41: 6 | H41: =F41/F40 | T41: =T40/T37 | U41: =U40/U37 | V41: =V40/V37 | W41: =W40/W37 | X41: =X40/X37 | Y41: =Y40/Y37 | Z41: =T41/AA41 | AA41: 0.4
...

Sheet Воронка новогодние
B3: W1 2024 | C3: W1 2024 | D3: W1 2024
B4: План | C4: Реальный план | D4: Факт
A5: Оплаты | B5: 7 | C5: 3 | D5: 1 | E5: (можно считать две)), вторая была 8 января
A6: Показы / Охват | B6: =B8/B7 | C6: =C8/C7 | D6: 157075
A7: CTR | B7: 0.004 | C7: 0.004 | D7: =D8/D6
A8: Клики | B8: =B10/B9 | C8: =C10/C9 | D8: 869
A9: CR клик-заявка | B9: 0.12 | C9: 0.12 | D9: =D10/D8
A10: Заявка | B10: =B12/B11 | C10: =C12/C11 | D10: 112
A11: CR заявка- ВУ | B11: 0.1 | C11: 0.1 | D11: =D12/D10
A12: ВУ | B12: =B5/B13 | C12: =C5/C13 | D12: 9
A13: CR ВУ в оплату | B13: 0.3 | C13: 0.3 | D13: =D5/D12
A14: CR в заявку - оплата | B14: 0.02 | C14: 0.02 | D14: =D5/D10
A15: Бюджет маркетинга | B15: =B8*B16 | C15: =C8*C16 | D15: 92340
A16: Цена клика | B16: 80 | C16: 80 | D16: =D15/D8
A17: Цена заявки | B17: =B15/B10 | C17: =C15/C10 | D17: =D15/D10
C21: План по продажам: 7 оплат на первой неделе: 3 оплаты с январских заявок W1, 4 добрать с декабрьских

Sheet Marketing сравнительно
B1: W49 | F1: W50 | J1: Спринт (W49-W50)
B2: 04.12-10.12 | F2: 11.12-17.12 | J2: 04.12-17.12
B3: Яндекс | C3: Телеграм | D3: Тотал | F3: Тотал | G3: Яндекс | H3: Телеграм | I3: Без меток | J3: Яндекс | K3: Телеграм | L3: Тотал | M3: План | N3: Факт
A4: N, Total | B4: 0 | C4: 0 | D4: =B4+C4 | F4: =G4+H4 | G4: 2 | H4: 2 | J4: 1 | K4: =C4+H4 | L4: =J4+K4 | O4: 3
A5: Показы / Охват | B5: 512999 | C5: 2021 | D5: =E5+F5 | F5: =G5+H5 | G5: 244516 | H5: 2377 | J5: =B5+G5 | K5: =C5+H5 | L5: =J5+K5 | O5: 128763
A6: CTR | B6: 0.0035009815 | C6: 0.082137556 | D6: =D7/D5 | F6: =F7/F5 | G6: =G7/G5 | H6: 0.087925957 | J6: =J7/J5 | K6: =K7/K5 | L6: =L7/L5 | O6: 0.0066012752
A7: Клики | B7: 1796 | C7: 166 | D7: =E7+F7 | F7: =G7+H7 | G7: 950 | H7: 209 | J7: =B7+G7 | K7: =C7+H7 | L7: =J7+K7 | O7: 850
A8: CR клик-заявка | B8: 0.041202673 | C8: 0.41566265 | D8: =D9/D7 | F8: =F9/F7 | G8: =G9/G7 | H8: 0.28708134 | J8: =J9/J7 | K8: =K9/K7 | L8: =L9/L7 | O8: 0.14470588
A9: Заявка | B9: 74 | C9: 69 | D9: =B9+C9 | F9: =G9+H9+I9 | G9: 107 | H9: 64 | I9: 1 | J9: 225 | K9: 136 | L9: =J9+K9 | O9: 123
A10: CR заявка- ВУ | B10: =B11/B9 | C10: =C11/C9 | D10: =D11/D9 | F10: =G10+H10 | G10: =G11/G9 | H10: 0.11666667 | J10: =J11/J9 | K10: =K11/K9 | L10: =L11/L9 | O10: 0.097560976
A11: ВУ (вводный урок) | B11: 16 | C11: 13 | D11: =B11+C11 | F11: =G11+H11+I11 | G11: 12 | H11: 8 | I11: 1 | J11: =B11+G11 | K11: =C11+H11 | L11: =J11+K11 | O11: 12
A12: CR ВУ в оплату | B12: 0 | C12: 0 | D12: =D4/D11 | F12: =F4/F11 | G12: =G4/G11 | H12: 0.28571429 | J12: =J4/J11 | K12: =K4/K11 | L12: =L4/L11 | O12: 0.25
A13: CR в заявку - оплата | B13: 0 | C13: 0 | D13: =D4/D9 | F13: =F4/F9 | G13: =G4/G9 | H13: =H4/H9 | J13: =J4/J9 | K13: =K4/K9 | L13: =L4/L9 | O13: 0.024390244
A14: Бюджет маркетинга | B14: 110534 | C14: 28632 | D14: =E14+F14 | F14: =G14+H14 | G14: 98492.8 | H14: 26714 | J14: =B14+G14 | K14: =C14+H14 | L14: =J14+K14 | O14: 123289.37
A15: Цена клика | B15: 215.46631 | C15: 14167.244 | D15: =E15+F15 | F15: =G15+H15 | G15: =G14/G7 | H15: 127.81818 | J15: =J14/J7 | K15: =K14/K7 | L15: =L14/L7 | O15: 3694.7776
A16: Цена заявки | B16: 61.544543 | C16: 172.48193 | D16: =E16+F16 | F16: =G16+H16 | G16: =G14/G9 | H16: 445.23333 | J16: =J14/J9 | K16: =K14/K9 | L16: =L14/L9 | O16: 145.04632
A17: СMC (Цена привлечения) | B17: 1493.7027 | C17: 414.95652 | G17: =G14/G4 | H17: 13357 | J17: =J14/J4 | K17: =K14/K4 | L17: =L14/L4 | O17: 1002.3526
A18: Стоимость ВУ | B18: 6908.375 | D18: =D14/D11 | F18: =F14/F11 | G18: =G14/G11 | H18: =H14/H11 | J18: =J14/J11 | K18: =K14/K11 | L18: =L14/L11 | O18: 41096.457
O19: 10274.114

Sheet Воронка по когортам
B1: 09.10-15.10 | D1: 16.10-22.10 | F1: 23.10-29.10 | H1: Х | J1: Х | L1: Х | N1: Х
B2: Yandex | C2: Telegram | D2: Yandex | E2: Telegram | F2: Yandex | G2: Telegram | H2: Yandex | I2: Telegram | J2: Yandex | K2: Telegram | L2: Yandex | M2: Telegram | N2: Yandex | O2: Telegram
A3: Бюджет
A4: Клики
A5: CPC | B5: =B3/B4 | C5: =C3/C4 | D5: =D3/D4 | E5: =E3/E4 | F5: =F3/F4 | G5: =G3/G4 | H5: =H3/H4 | I5: =I3/I4 | ... O5: =O3/O4
A6: Заявки
A7: CPL | B7: =B3/B6 | C7: =C3/C6 | D7: =D3/D6 | E7: =E3/E6 | F7: =F3/F6 | G7: =G3/G6 | H7: =H3/H6 | I7: =I3/I6 | ... O7: =O3/O6
A8: CR клик –> заявка | B8: =B6/B4 | C8: =C6/C4 | D8: =D6/D4 | E8: =E6/E4 | F8: =F6/F4 | G8: =G6/G4 | H8: =H6/H4 | I8: =I6/I4 | ... O8: =O6/O4
A9: Квалифицировано
A10: Стоимость квал заявки | B10: =#REF!/B9 | C10: =#REF!/C9 | D10: =#REF!/D9 | E10: =#REF!/E9 | F10: =#REF!/F9 | G10: =#REF!/G9 | H10: =#REF!/H9 | I10: =#REF!/I9 | ... O10: =#REF!/O9
A11: CR заявка –> квал заявка | B11: =B9/B3 | C11: =C9/C3 | D11: =D9/D3 | E11: =E9/E3 | F11: =F9/F3 | G11: =G9/G3 | H11: =H9/H3 | I11: =I9/I3 | ... O11: =O9/O3
A12: Записи на ВУ
A13: CPB | B13: =B3/B12 | C13: =C3/C12 | D13: =D3/D12 | E13: =E3/E12 | F13: =F3/F12 | G13: =G3/G12 | H13: =H3/H12 | I13: =I3/I12 | ... O13: =O3/O12
A14: CR заявка –> запись | B14: =B12/B6 | C14: =C12/C6 | D14: =D12/D6 | E14: =E12/E6 | F14: =F12/F6 | G14: =G12/G6 | H14: =H12/H6 | I14: =I12/I6 | ... O14: =O12/O6
A15: Проведение ВУ
A16: CPTC | B16: =B3/B15 | C16: =C3/C15 | D16: =D3/D15 | E16: =E3/E15 | F16: =F3/F15 | G16: =G3/G15 | H16: =H3/H15 | I16: =I3/I15 | ... O16: =O3/O15
A17: CR записи –> ВУ | B17: =B15/B12 | C17: =C15/C12 | D17: =D15/D12 | E17: =E15/E12 | F17: =F15/F12 | G17: =G15/G12 | H17: =H15/H12 | I17: =I15/I12 | ... O17: =O15/O12
A18: Клиенты
A19: C1 | B19: =B18/B15 | C19: =C18/C15 | D19: =D18/D15 | E19: =E18/E15 | F19: =F18/F15 | G19: =G18/G15 | H19: =H18/H15 | I19: =I18/I15 | ... O19: =O18/O15
A20: CMC | B20: =B3/B18 | C20: =C3/C18 | D20: =D3/D18 | E20: =E3/E18 | F20: =F3/F18 | G20: =G3/G18 | H20: =H3/H18 | I20: =I3/I18 | ... O20: =O3/O18
A21: AOV | B21: =B22/B18 | C21: =C22/C18 | D21: =D22/D18 | E21: =E22/E18 | F21: =F22/F18 | G21: =G22/G18 | H21: =H22/H18 | I21: =I22/I18 | ... O21: =O22/O18
A22: Revenue
A23: AOV/CMC | B23: =B21/B20 | C23: =C21/C20 | D23: =D21/D20 | E23: =E21/E20 | F23: =F21/F20 | G23: =G21/G20 | H23: =H21/H20 | I23: =I21/I20 | ... O23: =O21/O20

Sheet Клиенты оплаты
A1: Дата | B1: Name | C1: Менеджер | D1: utm_source | E1: utm_medium | F1: utm_campaign | G1: utm_term | H1: Amo | I1: Комментарий
A2: 45179 | B2: Наталья Голышева | C2: Захарченко Олег | D2: yandex | E2: cpc | F2: profprobi_prof | G2: ---autotargeting | H2: https://amoprofilum.amocrm.ru/leads/detail/25818791?tab_id=leads_31761678193899
A3: 45179 | B3: Светлана Ильяных | C3: Захарченко Олег | D3: yandex | E3: cpc | F3: profprobi_prof | G3: ---autotargeting | H3: https://amoprofilum.amocrm.ru/leads/detail/25842857
A4: 45182 | B4: Светлана | C4: Захарченко Олег | D4: offline | H4: https://amoprofilum.amocrm.ru/leads/detail/25845601?tab_id=leads_31761678193899
A5: 45184 | B5: Джамиля Борзая | C5: Захарченко Олег | D5: yandex | E5: cpc | F5: profprobi_it_program | G5: ---autotargeting | H5: https://amoprofilum.amocrm.ru/leads/detail/25826989?tab_id=leads_31761678193899
A6: 45185 | B6: Екатерина | C6: Захарченко Олег | D6: offline | H6: https://amoprofilum.amocrm.ru/leads/detail/25850133
A7: 45187 | B7: Анна Романова | C7: Захарченко Олег | D7: organic | H7: https://amoprofilum.amocrm.ru/leads/detail/25850609 | I7: Нет меток

Sheet Дашборд
F3: Аналитика по причине отказа | O3: За весь срок реализации
C6: кол-во | D6: Воронка сентябрь факт | E6: CR % | F6: CR %
B7: ='Вычисления'!A63 | C7: ='Вычисления'!B63 | D7: =REPT("I",'Вычисления'!B63/6) | E7: 100 | F7: 100
B8: ='Вычисления'!A64 | C8: ='Вычисления'!B64 | D8: =REPT("I",'Вычисления'!B64/6) | E8: ='Вычисления'!C64 | F8: ='Вычисления'!B64
B9: ='Вычисления'!A65 | C9: ='Вычисления'!B65 | D9: =REPT("I",'Вычисления'!B65/6) | E9: ='Вычисления'!C65 | F9: ='Вычисления'!B65
B10: ='Вычисления'!A66 | C10: ='Вычисления'!B66 | D10: =REPT("I",'Вычисления'!B66/6) | E10: ='Вычисления'!C66 | F10: ='Вычисления'!B66 | G10: Выручка
B11: ='Вычисления'!A67 | C11: ='Вычисления'!B67 | D11: =REPT("I",'Вычисления'!B67/6) | E11: ='Вычисления'!C67 | F11: ='Вычисления'!B67
C14: кол-во | D14: Воронка октябрь факт | E14: CR % факт | F14: CR % план
B15: сделки | C15: ='Вычисления'!B70 | D15: =REPT("I",'Вычисления'!B70/3) | E15: 1 | F15: ='Вычисления'!E70
B16: квалифицировано | C16: ='Вычисления'!B71 | D16: =REPT("I",'Вычисления'!B71/3) | E16: ='Вычисления'!C71 | F16: ='Вычисления'!E71
B17: назначено ВУ | C17: ='Вычисления'!B72 | D17: =REPT("I",'Вычисления'!B72/3) | E17: ='Вычисления'!C72 | F17: ='Вычисления'!E72
B18: ВУ состоялось | C18: ='Вычисления'!B73 | D18: =REPT("I",'Вычисления'!B73/3) | E18: ='Вычисления'!C73 | F18: ='Вычисления'!E73 | G18: Выручка
B19: Оплат | C19: ='Вычисления'!B74 | D19: =REPT("I",'Вычисления'!B74) | E19: ='Вычисления'!C74 | F19: ='Вычисления'!E74
C23: кол-во | D23: Воронка 03.11-30.11 факт | E23: CR % факт | F23: CR % план
B24: сделки | C24: 723 | D24: =REPT("I",C24/5) | E24: 1 | F24: 1
B25: квалифицировано | C25: 573 | D25: =REPT("I",C25/5) | E25: =C25/C24 | F25: ='Sales PnL(архив)'!AA8
B26: назначено ВУ | C26: 179 | D26: =REPT("I",C26/5) | E26: =C26/C25 | F26: ='Sales PnL(архив)'!AA10
B27: ВУ состоялось | C27: 74 | D27: =REPT("I",C27/5) | E27: =C27/C26 | F27: ='Sales PnL(архив)'!AA13 | G27: Выручка
B28: Оплат | C28: 3 | D28: =REPT("I",C28/3) | E28: =C28/C27 | F28: ='Sales PnL(архив)'!AA16

Sheet Задачи
A1: Название задачи | B1: Ответственная команда | C1: Дедлайн | D1: Ожидаемый результат | E1: Статус | F1: Зависимость | G1: Критерий готовности | H1: Приоритет | I1: ID | J1: Месяц
A2: Kick-off и governance проекта | B2: Management | C2: 06.06.2026 | D2: Запущен проект, согласованы роли, ритм синков и правила работы | E2: План | F2: — | G2: Все команды знают роли, owners и cadence | H2: Must | I2: MNG-01 | J2: Июнь
A3: Анализ тематик поддержки | B3: Analytics | C3: 13.06.2026 | D3: Пакет аналитики по структуре поддержки и линиям обработки | E3: План | F3: — | G3: Готова аналитика по топ-темам, кластерам и пересечениям | H3: Must | I3: ANL-01 | J3: Июнь
A4: Описание AS IS операционной обработки | B4: Operations | C4: 13.06.2026 | D4: Документ AS IS процесса обработки штрафов | E4: План | F4: — | G4: Описаны текущие ручные шаги, боли операторов и ограничения | H4: Must | I4: OPS-01 | J4: Июнь
A5: Матрица зависимостей проекта | B5: Management | C5: 13.06.2026 | D5: Dependency map по 7 командам | E5: План | F5: MNG-01 | G5: Согласованы входы/выходы между командами | H5: Must | I5: MNG-02 | J5: Июнь
A6: Анализ штрафных нарушений | B6: Analytics | C6: 13.06.2026 | D6: Выделены приоритетные типы нарушений для первой волны | E6: План | F6: — | G6: Есть матрица частота × автоматизируемость × цена ошибки | H6: Must | I6: ANL-02 | J6: Июнь
A7: AS IS процесса штрафов и pain points | B7: Product | C7: 20.06.2026 | D7: Карта текущего процесса и список болей | E7: План | F7: ANL-01; OPS-01 | G7: Есть согласованная карта процесса и проблем | H7: Must | I7: PRD-01 | J7: Июнь
A8: Сезонность и staffing forecast | B8: Analytics | C8: 20.06.2026 | D8: Прогноз нагрузки и staffing model | E8: План | F8: ANL-01; ANL-02 | G8: Есть помесячный прогноз и пиковый штат | H8: Must | I8: ANL-03 | J8: Июнь
A9: Приоритизация фич первой волны | B9: Product | C9: 20.06.2026 | D9: Список фич v1: intake, clarification, parking automation, review | E9: План | F9: ANL-02; ANL-03; PRD-01 | G9: Утверждён shortlist must-have фич | H9: Must | I9: PRD-02 | J9: Июнь
A10: Сбор корпуса текстов и правил | B10: Content | C10: 20.06.2026 | D10: Knowledge base: правила, FAQ, шаблоны сообщений | E10: План | F10: PRD-01 | G10: Есть базовый контент для UX и обучения | H10: Must | I10: CNT-01 | J10: Июнь
A11: Feasibility по нарушениям и границам AUTO/HYBRID | B11: ML | C11: 20.06.2026 | D11: ML feasibility note по типам нарушений | E11: План | F11: PRD-02 | G11: Согласованы границы автоматизации | H11: Must | I11: ML-01 | J11: Июнь
A12: Архитектурный draft и ERD | B12: ML-development | C12: 27.06.2026 | D12: Черновик архитектуры, pipeline и data model | E12: План | F12: PRD-02; ML-01 | G12: Архитектура и ERD согласованы | H12: Must | I12: MLD-01 | J12: Июнь
... A39: Чекпоинт 4, handover и итоговые артефакты | B39: Management | C39: 30.09.2026 | D39: CP4: rollout, monitoring, training, handover завершены | E39: План | F39: ANL-06; OPS-05; PRD-07 | G39: Заказчик получил полный пакет результатов | H39: Must | I39: MNG-06 | J39: Сентябрь

Sheet Порядок работы
B2: ПОРЯДОК СИНХРОНИЗАЦИИ
B4: Внедряем правила:
B5: 1. Внутри фокусных задач есть распределение:
B6: Запуски и эксперименты;
B7: Операционное развитие
B8: 2. Каждый берет на себя максимум 3-4 задачи, но зато они максимально должны выполняться
B9: 3. Суммарно в фокусах - не более 10ти задач, иначе получается mess, а не фокусы
B11: Обратить внимание!
B12: У каждого человека свое распределение фокуса между задачами.
B14: Изменения в регулярных синках:
B15: ПН - ПЛАНИРОВАНИЕ СПРИНТА (1Ч)
B16: ВТ, СР, ЧТ - 30-МИНУТКИ (В ПТ - в рамках 30минуток - подготовка к демо)
... B23: «Есть ли препятствия в моей работе?»

Sheet Вычисления
A1: Год | C1: Выбранный год | D1: Месяц числом | F1: Месяц | H1: Выбранный месяц
A2: {=UNIQUE('Оплаты план/факт'!C2:C1000)} | C2: ='Дашборд'!B3 | D2: =IFERROR(__xludf.DUMMYFUNCTION("unique(FILTER('Оплаты план/факт'!B2:B1000,'Оплаты план/факт'!C2:C1000=C2))"),"#REF!") | F2: =IFS(D2=1,"январь",D2=2,"февраль",D2=3,"март",D2=4,"апрель",D2=5,"май",D2=6,"июнь",D2=7,"июль",D2=8,"август",D2=9,"сентярбрь",D2=10,"октябрь",D2=11,"ноябрь",D2=12,"декабрь") | H2: ='Дашборд'!C3 | I2: =IFS(H2="сентябрь",9 , H2="октябрь",10)
F3: =IFS(D3=1,"январь",D3=2,"февраль",D3=3,"март",D3=4,"апрель",D3=5,"май",D3=6,"июнь",D3=7,"июль",D3=8,"август",D3=9,"сентябрь",D3=10,"октябрь",D3=11,"ноябрь",D3=12,"декабрь")
F4: =IFS(D4=1,"январь",D4=2,"февраль",D4=3,"март",D4=4,"апрель",D4=5,"май",D4=6,"июнь",D4=7,"июль",D4=8,"август",D4=9,"сентярбрь",D4=10,"октябрь",D4=11,"ноябрь",D4=12,"декабрь")
F5: =IFS(D5=1,"январь",D5=2,"февраль",D5=3,"март",D5=4,"апрель",D5=5,"май",D5=6,"июнь",D5=7,"июль",D5=8,"август",D5=9,"сентярбрь",D5=10,"октябрь",D5=11,"ноябрь",D5=12,"декабрь")
F6: =IFS(D6=1,"январь",D6=2,"февраль",D6=3,"март",D6=4,"апрель",D6=5,"май",D6=6,"июнь",D6=7,"июль",D6=8,"август",D6=9,"сентярбрь",D6=10,"октябрь",D6=11,"ноябрь",D6=12,"декабрь")
A14: Динамика показателей план/факт
A16: Выручка
A17: месяц | B17: факт | C17: план | D17: текущий процент выполнения плана
A18: сентябрь | B18: =SUMIFS('Оплаты план/факт'!D2:D1000,'Оплаты план/факт'!B2:B1000,"9") | C18: ='Оплаты план/факт'!K5 | D18: =B18/C18
A19: октябрь | B19: =SUMIFS('Оплаты план/факт'!D3:D1001,'Оплаты план/факт'!B3:B1001,"10") | C19: ='Оплаты план/факт'!L5 | D19: =B19/C19
A20: ноябрь | B20: =SUMIFS('Оплаты план/факт'!D4:D1002,'Оплаты план/факт'!B4:B1002,"11") | C20: ='Оплаты план/факт'!M5 | D20: =B20/C20
A21: декабрь | B21: =SUMIFS('Оплаты план/факт'!D5:D1003,'Оплаты план/факт'!B5:B1003,"12") | C21: ='Оплаты план/факт'!N5 | D21: =B21/C21
A22: январь | B22: =SUMIFS('Оплаты план/факт'!D6:D1004,'Оплаты план/факт'!B6:B1004,"1") | C22: 300000 | D22: =B22/C22
A25: Сводка
B26: факт | C26: план | D26: выполнения плана
B27: =IFERROR(__xludf.DUMMYFUNCTION("filter(B18:B22,A18:A22=H2)"),"#N/A") | C27: =IFERROR(__xludf.DUMMYFUNCTION("filter(C18:C22,A18:A22=H2)"),"#N/A") | D27: =IFERROR(__xludf.DUMMYFUNCTION("filter(D18:D22,A18:A22=H2)"),"#N/A")
F40: сентябрь | G40: октябрь | H40: ноябрь | I40: декабрь
A41: средний чек в выбранном месяце расчет | B41: =IFERROR(__xludf.DUMMYFUNCTION("QUERY('Оплаты план/факт'!A1:G1000, ""select avg(D) pivot B"",-1)"),"#REF!")
A43: средний чек общий | B43: =AVERAGE('Оплаты план/факт'!D2:D1000)
A44: средний чек в выбранном месяце | B44: =IFERROR(__xludf.DUMMYFUNCTION("FILTER(C42:I42,C40:I40=H2)"),"")
G49: сентябрь | H49: октябрь | I49: ноябрь | J49: декабрь | K49: выручка менеджера в выбранном месяце
B50: =IFERROR(__xludf.DUMMYFUNCTION("QUERY('Оплаты план/факт'!A1:G1000, ""select E, sum(D) group by E pivot B"",-1)"),"#REF!")
K52: =IFERROR(__xludf.DUMMYFUNCTION("FILTER(C52:J52,$C$49:$J$49=$H$2)"),"")
K53: =IFERROR(__xludf.DUMMYFUNCTION("FILTER(C53:J53,$C$49:$J$49=$H$2)"),"")
K54: =IFERROR(__xludf.DUMMYFUNCTION("FILTER(C54:J54,$C$49:$J$49=$H$2)"),"")
A57: кол-во оплат общее | B57: =COUNT('Оплаты план/факт'!D2:D1000)
A59: кол-во оплат в месяц
A62: воронка для построения | B62: факт | C62: конверсии факт | D62: план | E62: конверсии план (% от предыдущей стадии)
A63: сделки | B63: ='Sales PnL(архив)'!C5 | C63: 1 | D63: ='Sales PnL(архив)'!J5 | E63: 1
A64: квалифицировано | B64: ='Sales PnL(архив)'!C7 | C64: ='Sales PnL(архив)'!C8 | D64: ='Sales PnL(архив)'!J7 | E64: ='Sales PnL(архив)'!J8
A65: назначено ВУ | B65: ='Sales PnL(архив)'!C9 | C65: ='Sales PnL(архив)'!C10 | D65: ='Sales PnL(архив)'!J9 | E65: ='Sales PnL(архив)'!J10
A66: ВУ состоялось | B66: ='Sales PnL(архив)'!C12 | C66: ='Sales PnL(архив)'!C13 | D66: ='Sales PnL(архив)'!J12 | E66: ='Sales PnL(архив)'!J13
A67: Оплат | B67: ='Sales PnL(архив)'!C15 | C67: ='Sales PnL(архив)'!C16 | D67: ='Sales PnL(архив)'!J15 | E67: ='Sales PnL(архив)'!J16
A69: воронка для построения | B69: факт | C69: конверсии факт | D69: план | E69: конверсии план (% от предыдущей стадии)
A70: сделки | B70: ='Sales PnL(архив)'!K5 | C70: 1 | D70: ='Sales PnL(архив)'!S5 | E70: 1
A71: квалифицировано | B71: ='Sales PnL(архив)'!K7 | C71: ='Sales PnL(архив)'!K8 | D71: ='Sales PnL(архив)'!S7 | E71: ='Sales PnL(архив)'!S8
A72: назначено ВУ | B72: ='Sales PnL(архив)'!K9 | C72: ='Sales PnL(архив)'!K10 | D72: ='Sales PnL(архив)'!S9 | E72: ='Sales PnL(архив)'!S10
A73: ВУ состоялось | B73: ='Sales PnL(архив)'!K12 | D73: ='Sales PnL(архив)'!S12
A74: Оплат | B74: ='Sales PnL(архив)'!K15 | C74: ='Sales PnL(архив)'!K16 | D74: ='Sales PnL(архив)'!S15 | E74: ='Sales PnL(архив)'!S16

Sheet Синки_и_зависимости
A1: От кого | B1: Кому | C1: Что передаёт | D1: Когда | E1: Что блокирует
A2: Analytics | B2: Product | C2: Аналитику тем, нарушений, сезонности и staffing | D2: Июнь W2–W3 | E2: Без этого Product не финализирует PRD
A3: Product | B3: ML | C3: ТЗ по первой волне, policy, требования к моделям | D3: До конца июня | E3: Без этого ML не начинает целевую разработку
A4: Product | B4: ML-development | C4: PRD, архитектурные требования, decision logic | D4: Конец июня | E4: Без этого нельзя собирать интеграционный pipeline
A5: Content | B5: ML | C5: Тексты, шаблоны, корпус нарушений | D5: Июнь W3 – Июль W1 | E5: Без этого качество routing/clarification ниже
A6: ML | B6: ML-development | C6: First models / сценарии / API contracts | D6: Июль W2–W3 | E6: Без этого ML-dev не интегрирует MVP
A7: Product | B7: Operations | C7: UX flow, intake logic, review flow | D7: Июль W2–W3 | E7: Без этого Ops не может тестировать
A8: ML-development | B8: Operations | C8: Интегрированный тестовый контур | D8: Июль W4 | E8: Без этого нельзя начать closed test
A9: Operations | B9: Product | C9: Feedback по тесту и боли линии | D9: Август W1–W2 | E9: Без этого Product не выпускает v2 policy
A10: Operations | B10: ML | C10: Ошибки моделей, спорные кейсы, false positives | D10: Август W1–W2 | E10: Без этого ML не делает полезный retrain
A11: Operations | B11: Content | C11: Feedback по текстам, шаблонам, регламентам | D11: Август W1–W2 | E11: Без этого Content не финализирует материалы
A12: Product / ML / Content | B12: ML-development | C12: Финальные правки для release candidate | D12: Август W2–W4 | E12: Без этого rollout рискован
A13: ML-development + Content + Ops rules | B13: Operations | C13: Готовый production contour + инструкции | D13: Сентябрь W1 | E13: Без этого нельзя обучить и запустить линию

Sheet Чекпоинты
A1: Чекпоинт | B1: Срок | C1: Что должно быть готово | D1: Критичный риск при срыве
A2: CP1 | B2: 30.06.2026 | C2: Готовы аналитика нагрузки и прогноз тематик; утверждён и декомпозирован список продуктовых доработок; ML и ML-development получили ТЗ; Analytics передала данные Product | D2: Срыв всего критического пути: Product/ML/ML-dev стартуют поздно
A3: CP2 | B3: 31.07.2026 | C3: Прототипы форм и логика доуточнений готовы и согласованы; первые модели обучены и переданы на интеграцию; Content завершил v1 материалов | D3: Невозможно начать полноценный закрытый тест
A4: CP3 | B4: 31.08.2026 | C4: Все фичи прошли закрытое тестирование; feedback передан в ML; финальные регламенты утверждены; подтверждена готовность к запуску | D4: Rollout в сентябре становится рискованным или переносится
A5: CP4 | B5: 30.09.2026 | C5: Полный запуск завершён; мониторинг работает; операторы обучены и аттестованы; итоговые артефакты переданы заказчику | D5: Проект формально не считается доведённым до handover

Sheet Приоритеты
A1: Категория | B1: Описание
A2: Must-have | B2: Analytics и staffing model; PRD и intake/clarification flow; first models; MVP pipeline; closed test; release candidate; operator training; production rollout; monitoring; handover
A3: Should-have | B3: Backlog v2; post-launch tuning; расширенные дашборды; дополнительные UX-улучшения; развитие score/bonus/advanced ML после стабилизации
A4: Critical path | B4: Analytics → Product PRD → ML first models → ML-development integration → Operations testing → fixes → rollout
