Workbook

Sheet Финмодель индексация 1,5 года
B1: ОПиУ 2026-28 | C1: 2026 | O1: 2027 | AA1: 2028
B2: Название статьи | C2: Январь | D2: Февраль | E2: Март | F2: Апрель | G2: Май | H2: Июнь | I2: Июль | J2: Август | K2: Сентябрь | L2: Октябрь | M2: Ноябрь | N2: Декабрь | O2: Январь | P2: Февраль | Q2: Март | R2: Апрель | S2: Май | T2: Июнь | U2: Июль | V2: Август | W2: Сентябрь | X2: Октябрь | Y2: Ноябрь | Z2: Декабрь | AA2: Январь | AB2: Февраль | AC2: Март | AD2: Апрель | AE2: Май | AF2: Июнь | AG2: Июль | AH2: Август | AI2: Сентябрь | AJ2: Октябрь | AK2: Ноябрь | AL2: Декабрь
A4: 1.03 | B4: Выручка от реализации
A5: 3900 | B5: Выручка от комиссии | C5: =C20*C23*C24 -> 30057.504 | D5: =D20*D23*D24 -> 28198.205 | E5: =E20*E23*E24 -> 27039.854 | F5: =F20*F23*F24 -> 26375.031 | G5: =G20*G23*G24 -> 26058.598 | H5: =H20*H23*H24 -> 25989.016 | I5: =I20*I23*I24 -> 26095.269 | J5: =J20*J23*J24 -> 26327.705 | ... AL5: =AL20*AL23*AL24 -> 47366.215
B6: Выручка от подписки | C6: =C12*C25 -> 53539.5 | D6: =D12*D25 -> 50227.65 | E6: =E12*E25 -> 48164.355 | F6: =F12*F25 -> 46980.149 | G6: =G12*G25 -> 46416.506 | H6: =H12*H25 -> 46292.564 | I6: =I12*I25 -> 46481.825 | J6: =J12*J25 -> 46895.848 | ... AL6: =AL12*AL25 -> 95619.781
B7: Выручка от доставки | C7: =C20*C26 -> 110505.53 | D7: =D20*D26 -> 103669.87 | E7: =E20*E26 -> 99411.229 | F7: =F20*F26 -> 96967.027 | G7: =G20*G26 -> 95803.668 | H7: =H20*H26 -> 95547.853 | I7: =I20*I26 -> 95938.487 | J7: =J20*J26 -> 96793.031 | ... AL7: =AL20*AL26 -> 191877.03
B8: Общая выручка | C8: =SUM(C5:C7) -> 194102.53 | D8: =SUM(D5:D7) -> 182095.72 | E8: =SUM(E5:E7) -> 174615.44 | F8: =SUM(F5:F7) -> 170322.21 | G8: =SUM(G5:G7) -> 168278.77 | H8: =SUM(H5:H7) -> 167829.43 | I8: =SUM(I5:I7) -> 168515.58 | J8: =SUM(J5:J7) -> 170016.58 | ... AL8: =SUM(AL5:AL7) -> 334863.02
B9: Прирост выручки (% к прошлому месяцу) | C9: 1 | D9: =(D8/C8*100%)-100% -> -0.061858067 | E9: =(E8/D8*100%)-100% -> -0.041078868 | F9: =(F8/E8*100%)-100% -> -0.024586782 | G9: =(G8/F8*100%)-100% -> -0.011997462 | H9: =(H8/G8*100%)-100% -> -0.0026702084 | I9: =(I8/H8*100%)-100% -> 0.0040883667 | J9: =(J8/I8*100%)-100% -> 0.0089072081 | K9: =(K8/J8*100%)-100% -> 0.012303599 | ... AL9: =(AL8/AK8*100%)-100% -> 0.019999696
B11: Воронка продаж
A12: 0.02 | B12: Активная база клиентов | C12: =30594-30594*C14 -> 21415.8 | D12: =C12+D13-(C12*D14) -> 20091.06 | E12: =D12+E13-(D12*E14) -> 19265.742 | F12: =E12+F13-(E12*F14) -> 18792.059 | G12: =F12+G13-(F12*G14) -> 18566.602 | H12: =G12+H13-(G12*H14) -> 18517.026 | I12: =H12+I13-(H12*I14) -> 18592.73 | J12: =I12+J13-(I12*J14) -> 18758.339 | K12: =J12+K13-(J12*K14) -> 18989.134 | ... AL12: =AK12+AL13-(AK12*AL14) -> 31873.26
A13: 5000 | B13: Новые клиенты | C13: =$A$13 -> 5000 | D13: =C13+C13*$A$12 -> 5100 | E13: =D13+D13*$A$12 -> 5202 | F13: =E13+E13*$A$12 -> 5306.04 | G13: =F13+F13*$A$12 -> 5412.1608 | H13: =G13+G13*$A$12 -> 5520.404 | I13: =H13+H13*$A$12 -> 5630.8121 | J13: =I13+I13*$A$12 -> 5743.4283 | K13: =J13+J13*$A$12 -> 5858.2969 | ... AL13: =AK13+AK13*$A$12 -> 9999.4478
A14: 0.3 | B14: Отток | C14: =$A$14 -> 0.3 | D14: =$A$14 -> 0.3 | E14: =$A$14 -> 0.3 | F14: =$A$14 -> 0.3 | G14: =$A$14 -> 0.3 | H14: =$A$14 -> 0.3 | I14: =$A$14 -> 0.3 | J14: =$A$14 -> 0.3 | ... AL14: =$A$14 -> 0.3
A15: 495 | B15: База шеф-поваров | C15: =$A$15 -> 495 | D15: =C15+(D13/18)-(C15*15%) -> 704.08333 | E15: =D15+(E13/18)-(D15*15%) -> 887.47083 | F15: =E15+(F13/18)-(E15*15%) -> 1049.1302 | G15: =F15+(G13/18)-(F15*15%) -> 1192.4363 | H15: =G15+(H13/18)-(G15*15%) -> 1320.2599 | I15: =H15+(I13/18)-(H15*15%) -> 1435.0438 | J15: =I15+(J13/18)-(I15*15%) -> 1538.8666 | K15: =J15+(K13/18)-(J15*15%) -> 1633.4976 | ... AL15: =AK15+(AL13/18)-(AK15*15%) -> 3329.1822
B16: Заказчиков на одного повара | C16: =C12/C15 -> 43.264242 | D16: =D12/D15 -> 28.53506 | E16: =E12/E15 -> 21.708592 | F16: =F12/F15 -> 17.912037 | G16: =G12/G15 -> 15.57031 | H16: =H12/H15 -> 14.025288 | I16: =I12/I15 -> 12.95621 | J16: =J12/J15 -> 12.189711 | ... AL16: =AL12/AL15 -> 9.5739009
A17: 0.86 | B17: Процент успешных доставок | C17: =$A$17 -> 0.86 | D17: =$A$17 -> 0.86 | E17: =$A$17 -> 0.86 | F17: =$A$17 -> 0.86 | G17: =$A$17 -> 0.86 | H17: =$A$17 -> 0.86 | I17: =$A$17 -> 0.86 | J17: =$A$17 -> 0.86 | ... AL17: =$A$17 -> 0.86
A18: 2 | B18: Частотность созданных заказов | C18: =$A$18+RANDBETWEEN(-0.4, 0.1) -> 2 | D18: =$A$18+RANDBETWEEN(-0.4, 0.1) -> 2 | E18: =$A$18+RANDBETWEEN(-0.4, 0.1) -> 2 | F18: =$A$18+RANDBETWEEN(-0.4, 0.1) -> 2 | G18: =$A$18+RANDBETWEEN(-0.4, 0.1) -> 2 | H18: =$A$18+RANDBETWEEN(-0.4, 0.1) -> 2 | I18: =$A$18+RANDBETWEEN(-0.4, 0.1) -> 2 | J18: =$A$18+RANDBETWEEN(-0.4, 0.1) -> 2 | ... AL18: =$A$18+RANDBETWEEN(-0.4, 0.1) -> 2
B19: Созданные заказы | C19: =C12*C18 -> 42831.6 | D19: =D12*D18 -> 40182.12 | E19: =E12*E18 -> 38531.484 | F19: =F12*F18 -> 37584.119 | G19: =G12*G18 -> 37133.205 | H19: =H12*H18 -> 37034.051 | I19: =I12*I18 -> 37185.46 | J19: =J12*J18 -> 37516.679 | ... AL19: =AL12*AL18 -> 63746.521
B20: Выполненные заказы | C20: =C19*C17 -> 36835.176 | D20: =D19*D17 -> 34556.623 | E20: =E19*E17 -> 33137.076 | F20: =F19*F17 -> 32322.342 | G20: =G19*G17 -> 31934.556 | H20: =H19*H17 -> 31849.284 | I20: =I19*I17 -> 31979.496 | J20: =J19*J17 -> 32264.344 | ... AL20: =AL19*AL17 -> 54822.008
B22: Юнит-экономика
A23: 6.8 | B23: Средняя стоимость обеда | C23: =$A$23 -> 6.8 | D23: =$A$23 -> 6.8 | E23: =$A$23 -> 6.8 | F23: =$A$23 -> 6.8 | G23: =$A$23 -> 6.8 | H23: =$A$23 -> 6.8 | I23: =$A$23 -> 6.8 | J23: =$A$23 -> 6.8 | ... N23: =$A$23 -> 6.8 | O23: =$A$23+0.2 -> 7 | P23: =$A$23+0.2 -> 7 | Q23: =$A$23+0.2 -> 7 | R23: =$A$23+0.2 -> 7 | S23: =$A$23+0.2 -> 7 | T23: =$A$23+0.2 -> 7 | U23: =$A$23+0.2 -> 7 | V23: =$A$23+0.2 -> 7 | ... Z23: =$A$23+0.2 -> 7 | AA23: =$A$23+0.4 -> 7.2 | AB23: =$A$23+0.4 -> 7.2 | AC23: =$A$23+0.4 -> 7.2 | AD23: =$A$23+0.4 -> 7.2 | AE23: =$A$23+0.4 -> 7.2 | AF23: =$A$23+0.4 -> 7.2 | AG23: =$A$23+0.4 -> 7.2 | AH23: =$A$23+0.4 -> 7.2 | ... AL23: =$A$23+0.4 -> 7.2
A24: 0.12 | B24: Комиссия сервиса с шефов | C24: =$A$24 -> 0.12 | D24: =$A$24 -> 0.12 | E24: =$A$24 -> 0.12 | F24: =$A$24 -> 0.12 | G24: =$A$24 -> 0.12 | H24: =$A$24 -> 0.12 | I24: =$A$24 -> 0.12 | J24: =$A$24 -> 0.12 | ... AL24: =$A$24 -> 0.12
A25: 2.5 | B25: Стоимость подписки на сервис | C25: =$A$25 -> 2.5 | D25: =$A$25 -> 2.5 | E25: =$A$25 -> 2.5 | F25: =$A$25 -> 2.5 | G25: =$A$25 -> 2.5 | H25: =$A$25 -> 2.5 | I25: =$A$25 -> 2.5 | J25: =$A$25 -> 2.5 | ... T25: =$A$25 -> 2.5 | U25: =$A$25+0.5 -> 3 | V25: =$A$25+0.5 -> 3 | W25: =$A$25+0.5 -> 3 | X25: =$A$25+0.5 -> 3 | Y25: =$A$25+0.5 -> 3 | Z25: =$A$25+0.5 -> 3 | AA25: =$A$25+0.5 -> 3 | AB25: =$A$25+0.5 -> 3 | ... AL25: =$A$25+0.5 -> 3
A26: 3 | B26: Стоимость доставки | C26: =$A$26 -> 3 | D26: =$A$26 -> 3 | E26: =$A$26 -> 3 | F26: =$A$26 -> 3 | G26: =$A$26 -> 3 | H26: =$A$26 -> 3 | I26: =$A$26 -> 3 | J26: =$A$26 -> 3 | ... T26: =$A$26 -> 3 | U26: =$A$26+0.5 -> 3.5 | V26: =$A$26+0.5 -> 3.5 | W26: =$A$26+0.5 -> 3.5 | X26: =$A$26+0.5 -> 3.5 | Y26: =$A$26+0.5 -> 3.5 | Z26: =$A$26+0.5 -> 3.5 | AA26: =$A$26+0.5 -> 3.5 | AB26: =$A$26+0.5 -> 3.5 | ... AL26: =$A$26+0.5 -> 3.5
A27: 0.85 | B27: Скидки на 1 пользователя в месяц | C27: =$A$27 -> 0.85 | D27: =$A$27 -> 0.85 | E27: =D27-0.05 -> 0.8 | F27: =E27-0.05 -> 0.75 | G27: =F27-0.05 -> 0.7 | H27: =G27-0.05 -> 0.65 | I27: =H27-0.05 -> 0.6 | J27: =I27-0.05 -> 0.55 | K27: =J27-0.05 -> 0.5 | L27: =K27 -> 0.5 | M27: =L27 -> 0.5 | N27: =M27 -> 0.5 | O27: =N27 -> 0.5 | P27: =O27 -> 0.5 | Q27: =P27 -> 0.5 | R27: =Q27 -> 0.5 | S27: =R27 -> 0.5 | ... AL27: =AK27 -> 0.5
A28: 125 | B28: Бонусы на 1 курьера в месяц | C28: =$A$28 - (ROUND($C$29,0)-ROUND(C29,0))*10 -> 125 | D28: =$A$28 - (ROUND($C$29,0)-ROUND(D29,0))*10 -> 105 | E28: =$A$28 - (ROUND($C$29,0)-ROUND(E29,0))*10 -> 95 | F28: =$A$28 - (ROUND($C$29,0)-ROUND(F29,0))*10 -> 85 | G28: =$A$28 - (ROUND($C$29,0)-ROUND(G29,0))*10 -> 75 | H28: =$A$28 - (ROUND($C$29,0)-ROUND(H29,0))*10 -> 65 | I28: =$A$28 - (ROUND($C$29,0)-ROUND(I29,0))*10 -> 65 | J28: =$A$28 - (ROUND($C$29,0)-ROUND(J29,0))*10 -> 65 | ... AL28: =$A$28 - (ROUND($C$29,0)-ROUND(AL29,0))*10 -> 75
B29: Заказы в день на курьера | C29: =(C20/C30)/31 -> 12.5077 | D29: =(D20/D30)/31 -> 11.392231 | E29: =(E20/E30)/31 -> 9.9311371 | F29: =(F20/F30)/31 -> 8.8063295 | G29: =(G20/G30)/31 -> 7.9097053 | H29: =(H20/H30)/31 -> 7.1714407 | I29: =(I20/I30)/31 -> 6.5461456 | J29: =(J20/J30)/31 -> 6.6044535 | ... AL29: =(AL20/AL30)/31 -> 7.8571654
A30: 95 | B30: Кол-во курьеров | C30: =A30 -> 95 | D30: =C30*103% -> 97.85 | E30: =D30*110% -> 107.635 | F30: =E30*110% -> 118.3985 | G30: =F30*110% -> 130.23835 | H30: =G30*110% -> 143.26219 | I30: =H30*110% -> 157.5884 | J30: =I30 -> 157.5884 | K30: =J30 -> 157.5884 | L30: =K30 -> 157.5884 | M30: =L30 -> 157.5884 | N30: =M30 -> 157.5884 | O30: =N30 -> 157.5884 | P30: =O30 -> 157.5884 | Q30: =P30 -> 157.5884 | ... T30: =S30 -> 157.5884 | U30: =T30*102% -> 160.74017 | V30: =U30*102% -> 163.95498 | W30: =V30*102% -> 167.23407 | X30: =W30*102% -> 170.57876 | Y30: =X30*102% -> 173.99033 | Z30: =Y30*102% -> 177.47014 | AA30: =Z30*102% -> 181.01954 | AB30: =AA30*102% -> 184.63993 | ... AL30: =AK30*102% -> 225.07505
A31: 8 | B31: Кол-во сотрудников | C31: =$A$31 -> 8 | D31: =$A$31 -> 8 | E31: =$A$31 -> 8 | F31: =$A$31 -> 8 | G31: =$A$31 -> 8 | H31: =$A$31 -> 8 | I31: =$A$31 -> 8 | J31: =$A$31 -> 8 | K31: =$A$31 -> 8 | L31: =$A$31+1 -> 9 | M31: =$A$31+1 -> 9 | N31: =$A$31+1 -> 9 | O31: =$A$31+1 -> 9 | P31: =$A$31+1 -> 9 | Q31: =$A$31+2 -> 10 | R31: =$A$31+2 -> 10 | S31: =$A$31+2 -> 10 | T31: =$A$31+2 -> 10 | U31: =$A$31+2 -> 10 | V31: =$A$31+2 -> 10 | W31: =$A$31+2 -> 10 | X31: =$A$31+3 -> 11 | Y31: =$A$31+3 -> 11 | Z31: =$A$31+3 -> 11 | AA31: =$A$31+3 -> 11 | AB31: =$A$31+3 -> 11 | AC31: =$A$31+3 -> 11 | AD31: =$A$31+3 -> 11 | AE31: =$A$31+4 -> 12 | AF31: =$A$31+4 -> 12 | AG31: =$A$31+4 -> 12 | AH31: =$A$31+4 -> 12 | AI31: =$A$31+4 -> 12 | AJ31: =$A$31+4 -> 12 | AK31: =$A$31+4 -> 12 | AL31: =$A$31+4 -> 12
A32: 7.5 | B32: CAC | C32: =$A$32 -> 7.5 | D32: =$A$32 -> 7.5 | E32: =$A$32 -> 7.5 | F32: =$A$32 -> 7.5 | G32: =$A$32 -> 7.5 | H32: =$A$32 -> 7.5 | I32: =$A$32 -> 7.5 | J32: =$A$32 -> 7.5 | ... N32: =$A$32 -> 7.5 | O32: =$A$32*105% -> 7.875 | P32: =$A$32*105% -> 7.875 | Q32: =$A$32*105% -> 7.875 | R32: =$A$32*105% -> 7.875 | S32: =$A$32*105% -> 7.875 | T32: =$A$32*105% -> 7.875 | U32: =$A$32*105% -> 7.875 | V32: =$A$32*105% -> 7.875 | ... Z32: =$A$32*105% -> 7.875 | AA32: =$A$32*112% -> 8.4 | AB32: =$A$32*112% -> 8.4 | AC32: =$A$32*112% -> 8.4 | AD32: =$A$32*112% -> 8.4 | AE32: =$A$32*112% -> 8.4 | AF32: =$A$32*112% -> 8.4 | AG32: =$A$32*112% -> 8.4 | AH32: =$A$32*112% -> 8.4 | ... AL32: =$A$32*112% -> 8.4
B34: Расходы | C34: =SUM(C35:C40) -> 191487.58 | D34: =SUM(D35:D40) -> 184384.05 | E34: =SUM(E35:E40) -> 180241.34 | F34: =SUM(F35:F40) -> 177708.49 | G34: =SUM(G35:G40) -> 176238.46 | H34: =SUM(H35:H40) -> 175442.03 | I34: =SUM(I35:I40) -> 176613.84 | J34: =SUM(J35:J40) -> 177260.82 | ... AL34: =SUM(AL35:AL40) -> 304946.64
A35: 5300 | B35: Аренда | C35: =$A$35 -> 5300 | D35: =$A$35 -> 5300 | E35: =$A$35 -> 5300 | F35: =$A$35 -> 5300 | G35: =$A$35 -> 5300 | H35: =$A$35 -> 5300 | I35: =$A$35 -> 5300 | J35: =$A$35 -> 5300 | ... N35: =$A$35 -> 5300 | O35: =$A$35*110% -> 5830 | P35: =$A$35*110% -> 5830 | Q35: =$A$35*110% -> 5830 | R35: =$A$35*110% -> 5830 | S35: =$A$35*110% -> 5830 | T35: =$A$35*110% -> 5830 | U35: =$A$35*110% -> 5830 | V35: =$A$35*110% -> 5830 | ... Z35: =$A$35*110% -> 5830 | AA35: =$A$35*115% -> 6095 | AB35: =$A$35*115% -> 6095 | AC35: =$A$35*115% -> 6095 | AD35: =$A$35*115% -> 6095 | AE35: =$A$35*115% -> 6095 | AF35: =$A$35*115% -> 6095 | AG35: =$A$35*115% -> 6095 | AH35: =$A$35*115% -> 6095 | ... AL35: =$A$35*115% -> 6095
A36: 4000 | B36: ФОТ | C36: =$A$36*C31 -> 32000 | D36: =$A$36*D31 -> 32000 | E36: =$A$36*E31 -> 32000 | F36: =$A$36*F31 -> 32000 | G36: =$A$36*G31 -> 32000 | H36: =$A$36*H31 -> 32000 | I36: =$A$36*I31 -> 32000 | J36: =$A$36*J31 -> 32000 | ... N36: =$A$36*N31 -> 36000 | O36: =$A$36*O31*105% -> 37800 | P36: =$A$36*P31*105% -> 37800 | Q36: =$A$36*Q31*105% -> 42000 | R36: =$A$36*R31*105% -> 42000 | S36: =$A$36*S31*105% -> 42000 | T36: =$A$36*T31*105% -> 42000 | U36: =$A$36*U31*105% -> 42000 | V36: =$A$36*V31*105% -> 42000 | ... Z36: =$A$36*Z31*105% -> 46200 | AA36: =$A$36*AA31*110% -> 48400 | AB36: =$A$36*AB31*110% -> 48400 | AC36: =$A$36*AC31*110% -> 48400 | AD36: =$A$36*AD31*110% -> 48400 | AE36: =$A$36*AE31*110% -> 52800 | AF36: =$A$36*AF31*110% -> 52800 | AG36: =$A$36*AG31*110% -> 52800 | AH36: =$A$36*AH31*110% -> 52800 | ... AL36: =$A$36*AL31*110% -> 52800
B37: Бюджет на маркетинг | C37: =C13*C32 -> 37500 | D37: =D13*D32 -> 38250 | E37: =E13*E32 -> 39015 | F37: =F13*F32 -> 39795.3 | G37: =G13*G32 -> 40591.206 | H37: =H13*H32 -> 41403.03 | I37: =I13*I32 -> 42231.091 | J37: =J13*J32 -> 43075.713 | ... AL37: =AL13*AL32 -> 83995.361
B38: Затраты на скидки | C38: =C12*C27 -> 18203.43 | D38: =D12*D27 -> 17077.401 | E38: =E12*E27 -> 15412.594 | F38: =F12*F27 -> 14094.045 | G38: =G12*G27 -> 12996.622 | H38: =H12*H27 -> 12036.067 | I38: =I12*I27 -> 11155.638 | J38: =J12*J27 -> 10317.087 | ... AL38: =AL12*AL27 -> 15936.63
A39: 2.25 | B39: Выплаты курьерам за доставку | C39: =C20*$A$39 + C28*C30 -> 94754.146 | D39: =D20*$A$39 + D28*D30 -> 88026.652 | E39: =E20*$A$39 + E28*E30 -> 84783.747 | F39: =F20*$A$39 + F28*F30 -> 82789.142 | G39: =G20*$A$39 + G28*G30 -> 81620.627 | H39: =H20*$A$39 + H28*H30 -> 80972.931 | I39: =I20*$A$39 + I28*I30 -> 82197.112 | J39: =J20*$A$39 + J28*J30 -> 82838.02 | ... AL39: =AL20*$A$39 + AL28*AL30 -> 140230.15
B40: Прочие операционные расходы | C40: =SUM(C35:C36)*10% -> 3730 | D40: =SUM(D35:D36)*10% -> 3730 | E40: =SUM(E35:E36)*10% -> 3730 | F40: =SUM(F35:F36)*10% -> 3730 | G40: =SUM(G35:G36)*10% -> 3730 | H40: =SUM(H35:H36)*10% -> 3730 | I40: =SUM(I35:I36)*10% -> 3730 | J40: =SUM(J35:J36)*10% -> 3730 | ... AL40: =SUM(AL35:AL36)*10% -> 5889.5
B41: Прирост расходов (% к прошлому месяцу) | C41: 1 | D41: =(D34/C34)-100% -> -0.037096521 | E41: =(E34/D34)-100% -> -0.022467849 | F41: =(F34/E34)-100% -> -0.014052565 | G41: =(G34/F34)-100% -> -0.008272153 | H41: =(H34/G34)-100% -> -0.0045190302 | I41: =(I34/H34)-100% -> 0.0066791986 | J41: =(J34/I34)-100% -> 0.0036632378 | K41: =(K34/J34)-100% -> 0.0052587584 | ... AL41: =(AL34/AK34)-100% -> 0.015684313
B43: EBITDA (операционная прибыль) | C43: =C8-C34 -> 2614.9556 | D43: =D8-D34 -> -2288.3291 | E43: =E8-E34 -> -5625.9022 | F43: =F8-F34 -> -7386.2807 | G43: =G8-G34 -> -7959.6831 | H43: =H8-H34 -> -7612.5956 | I43: =I8-I34 -> -8098.2595 | J43: =J8-J34 -> -7244.2346 | ... AL43: =AL8-AL34 -> 29916.387
B44: EBITDA нарастающим итогом | C44: =C43 -> 2614.9556 | D44: =D43+C44 -> 326.62655 | E44: =E43+D44 -> -5299.2757 | F44: =F43+E44 -> -12685.556 | G44: =G43+F44 -> -20645.239 | H44: =H43+G44 -> -28257.835 | I44: =I43+H44 -> -36356.095 | J44: =J43+I44 -> -43600.329 | K44: =K43+J44 -> -49684.92 | ... AL44: =AL43+AK44 -> 217591.36
B45: Рентабельность EBITDA (% от общей выручки) | C45: =C43/C8 -> 0.013472033 | D45: =D43/D8 -> -0.012566627 | E45: =E43/E8 -> -0.032218813 | F45: =F43/F8 -> -0.043366516 | G45: =G43/G8 -> -0.047300578 | H45: =H43/H8 -> -0.045359121 | I45: =I43/I8 -> -0.048056444 | J45: =J43/J8 -> -0.042608988 | ... AL45: =AL43/AL8 -> 0.089339176
...

Sheet Финмодель индексация через год
B1: ОПиУ 2026-28 | C1: 2026 | O1: 2027 | AA1: 2028
B2: Название статьи | C2: Январь | D2: Февраль | E2: Март | F2: Апрель | G2: Май | H2: Июнь | I2: Июль | J2: Август | K2: Сентябрь | L2: Октябрь | M2: Ноябрь | N2: Декабрь | O2: Январь | P2: Февраль | Q2: Март | R2: Апрель | S2: Май | T2: Июнь | U2: Июль | V2: Август | W2: Сентябрь | X2: Октябрь | Y2: Ноябрь | Z2: Декабрь | AA2: Январь | AB2: Февраль | AC2: Март | AD2: Апрель | AE2: Май | AF2: Июнь | AG2: Июль | AH2: Август | AI2: Сентябрь | AJ2: Октябрь | AK2: Ноябрь | AL2: Декабрь
A4: 1.03 | B4: Выручка от реализации
A5: 3900 | B5: Выручка от комиссии | C5: =C20*C23*C24 -> 30057.504 | D5: =D20*D23*D24 -> 28198.205 | E5: =E20*E23*E24 -> 27039.854 | F5: =F20*F23*F24 -> 26375.031 | G5: =G20*G23*G24 -> 26058.598 | H5: =H20*H23*H24 -> 25989.016 | I5: =I20*I23*I24 -> 26095.269 | J5: =J20*J23*J24 -> 26327.705 | ... AL5: =AL20*AL23*AL24 -> 47366.215
B6: Выручка от подписки | C6: =C12*C25 -> 53539.5 | D6: =D12*D25 -> 50227.65 | E6: =E12*E25 -> 48164.355 | F6: =F12*F25 -> 46980.149 | G6: =G12*G25 -> 46416.506 | H6: =H12*H25 -> 46292.564 | I6: =I12*I25 -> 46481.825 | J6: =J12*J25 -> 46895.848 | ... AL6: =AL12*AL25 -> 111556.41
B7: Выручка от доставки | C7: =C20*C26 -> 110505.53 | D7: =D20*D26 -> 103669.87 | E7: =E20*E26 -> 99411.229 | F7: =F20*F26 -> 96967.027 | G7: =G20*G26 -> 95803.668 | H7: =H20*H26 -> 95547.853 | I7: =I20*I26 -> 95938.487 | J7: =J20*J26 -> 96793.031 | ... AL7: =AL20*AL26 -> 219288.03
B8: Общая выручка | C8: =SUM(C5:C7) -> 194102.53 | D8: =SUM(D5:D7) -> 182095.72 | E8: =SUM(E5:E7) -> 174615.44 | F8: =SUM(F5:F7) -> 170322.21 | G8: =SUM(G5:G7) -> 168278.77 | H8: =SUM(H5:H7) -> 167829.43 | I8: =SUM(I5:I7) -> 168515.58 | J8: =SUM(J5:J7) -> 170016.58 | ... AL8: =SUM(AL5:AL7) -> 378210.66
B9: Прирост выручки (% к прошлому месяцу) | C9: 1 | D9: =(D8/C8*100%)-100% -> -0.061858067 | E9: =(E8/D8*100%)-100% -> -0.041078868 | F9: =(F8/E8*100%)-100% -> -0.024586782 | G9: =(G8/F8*100%)-100% -> -0.011997462 | H9: =(H8/G8*100%)-100% -> -0.0026702084 | I9: =(I8/H8*100%)-100% -> 0.0040883667 | J9: =(J8/I8*100%)-100% -> 0.0089072081 | K9: =(K8/J8*100%)-100% -> 0.012303599 | ... AL9: =(AL8/AK8*100%)-100% -> 0.019999696
B11: Воронка продаж
A12: 0.02 | B12: Активная база клиентов | C12: =30594-30594*C14 -> 21415.8 | D12: =C12+D13-(C12*D14) -> 20091.06 | E12: =D12+E13-(D12*E14) -> 19265.742 | F12: =E12+F13-(E12*F14) -> 18792.059 | G12: =F12+G13-(F12*G14) -> 18566.602 | H12: =G12+H13-(G12*H14) -> 18517.026 | I12: =H12+I13-(H12*I14) -> 18592.73 | J12: =I12+J13-(I12*J14) -> 18758.339 | K12: =J12+K13-(J12*K14) -> 18989.134 | ... AL12: =AK12+AL13-(AK12*AL14) -> 31873.26
A13: 5000 | B13: Новые клиенты | C13: =$A$13 -> 5000 | D13: =C13+C13*$A$12 -> 5100 | E13: =D13+D13*$A$12 -> 5202 | F13: =E13+E13*$A$12 -> 5306.04 | G13: =F13+F13*$A$12 -> 5412.1608 | H13: =G13+G13*$A$12 -> 5520.404 | I13: =H13+H13*$A$12 -> 5630.8121 | J13: =I13+I13*$A$12 -> 5743.4283 | K13: =J13+J13*$A$12 -> 5858.2969 | ... AL13: =AK13+AK13*$A$12 -> 9999.4478
A14: 0.3 | B14: Отток | C14: =$A$14 -> 0.3 | D14: =$A$14 -> 0.3 | E14: =$A$14 -> 0.3 | F14: =$A$14 -> 0.3 | G14: =$A$14 -> 0.3 | H14: =$A$14 -> 0.3 | I14: =$A$14 -> 0.3 | J14: =$A$14 -> 0.3 | ... AL14: =$A$14 -> 0.3
A15: 495 | B15: База шеф-поваров | C15: =$A$15 -> 495 | D15: =C15+(D13/18)-(C15*15%) -> 704.08333 | E15: =D15+(E13/18)-(D15*15%) -> 887.47083 | F15: =E15+(F13/18)-(E15*15%) -> 1049.1302 | G15: =F15+(G13/18)-(F15*15%) -> 1192.4363 | H15: =G15+(H13/18)-(G15*15%) -> 1320.2599 | I15: =H15+(I13/18)-(H15*15%) -> 1435.0438 | J15: =I15+(J13/18)-(I15*15%) -> 1538.8666 | K15: =J15+(K13/18)-(J15*15%) -> 1633.4976 | ... AL15: =AK15+(AL13/18)-(AK15*15%) -> 3329.1822
B16: Заказчиков на одного повара | C16: =C12/C15 -> 43.264242 | D16: =D12/D15 -> 28.53506 | E16: =E12/E15 -> 21.708592 | F16: =F12/F15 -> 17.912037 | G16: =G12/G15 -> 15.57031 | H16: =H12/H15 -> 14.025288 | I16: =I12/I15 -> 12.95621 | J16: =J12/J15 -> 12.189711 | ... AL16: =AL12/AL15 -> 9.5739009
A17: 0.86 | B17: Процент успешных доставок | C17: =$A$17 -> 0.86 | D17: =$A$17 -> 0.86 | E17: =$A$17 -> 0.86 | F17: =$A$17 -> 0.86 | G17: =$A$17 -> 0.86 | H17: =$A$17 -> 0.86 | I17: =$A$17 -> 0.86 | J17: =$A$17 -> 0.86 | ... AL17: =$A$17 -> 0.86
A18: 2 | B18: Частотность созданных заказов | C18: =$A$18+RANDBETWEEN(-0.4, 0.1) -> 2 | D18: =$A$18+RANDBETWEEN(-0.4, 0.1) -> 2 | E18: =$A$18+RANDBETWEEN(-0.4, 0.1) -> 2 | F18: =$A$18+RANDBETWEEN(-0.4, 0.1) -> 2 | G18: =$A$18+RANDBETWEEN(-0.4, 0.1) -> 2 | H18: =$A$18+RANDBETWEEN(-0.4, 0.1) -> 2 | I18: =$A$18+RANDBETWEEN(-0.4, 0.1) -> 2 | J18: =$A$18+RANDBETWEEN(-0.4, 0.1) -> 2 | ... AL18: =$A$18+RANDBETWEEN(-0.4, 0.1) -> 2
B19: Созданные заказы | C19: =C12*C18 -> 42831.6 | D19: =D12*D18 -> 40182.12 | E19: =E12*E18 -> 38531.484 | F19: =F12*F18 -> 37584.119 | G19: =G12*G18 -> 37133.205 | H19: =H12*H18 -> 37034.051 | I19: =I12*I18 -> 37185.46 | J19: =J12*J18 -> 37516.679 | ... AL19: =AL12*AL18 -> 63746.521
B20: Выполненные заказы | C20: =C19*C17 -> 36835.176 | D20: =D19*D17 -> 34556.623 | E20: =E19*E17 -> 33137.076 | F20: =F19*F17 -> 32322.342 | G20: =G19*G17 -> 31934.556 | H20: =H19*H17 -> 31849.284 | I20: =I19*I17 -> 31979.496 | J20: =J19*J17 -> 32264.344 | ... AL20: =AL19*AL17 -> 54822.008
B22: Юнит-экономика
A23: 6.8 | B23: Средняя стоимость обеда | C23: =$A$23 -> 6.8 | D23: =$A$23 -> 6.8 | E23: =$A$23 -> 6.8 | F23: =$A$23 -> 6.8 | G23: =$A$23 -> 6.8 | H23: =$A$23 -> 6.8 | I23: =$A$23 -> 6.8 | J23: =$A$23 -> 6.8 | ... N23: =$A$23 -> 6.8 | O23: =$A$23+0.2 -> 7 | P23: =$A$23+0.2 -> 7 | Q23: =$A$23+0.2 -> 7 | R23: =$A$23+0.2 -> 7 | S23: =$A$23+0.2 -> 7 | T23: =$A$23+0.2 -> 7 | U23: =$A$23+0.2 -> 7 | V23: =$A$23+0.2 -> 7 | ... Z23: =$A$23+0.2 -> 7 | AA23: =$A$23+0.4 -> 7.2 | AB23: =$A$23+0.4 -> 7.2 | AC23: =$A$23+0.4 -> 7.2 | AD23: =$A$23+0.4 -> 7.2 | AE23: =$A$23+0.4 -> 7.2 | AF23: =$A$23+0.4 -> 7.2 | AG23: =$A$23+0.4 -> 7.2 | AH23: =$A$23+0.4 -> 7.2 | ... AL23: =$A$23+0.4 -> 7.2
A24: 0.12 | B24: Комиссия сервиса с шефов | C24: =$A$24 -> 0.12 | D24: =$A$24 -> 0.12 | E24: =$A$24 -> 0.12 | F24: =$A$24 -> 0.12 | G24: =$A$24 -> 0.12 | H24: =$A$24 -> 0.12 | I24: =$A$24 -> 0.12 | J24: =$A$24 -> 0.12 | ... AL24: =$A$24 -> 0.12
A25: 2.5 | B25: Стоимость подписки на сервис | C25: =$A$25 -> 2.5 | D25: =$A$25 -> 2.5 | E25: =$A$25 -> 2.5 | F25: =$A$25 -> 2.5 | G25: =$A$25 -> 2.5 | H25: =$A$25 -> 2.5 | I25: =$A$25 -> 2.5 | J25: =$A$25 -> 2.5 | ... N25: =$A$25 -> 2.5 | O25: =$A$25+0.5 -> 3 | P25: =$A$25+0.5 -> 3 | Q25: =$A$25+0.5 -> 3 | R25: =$A$25+0.5 -> 3 | S25: =$A$25+0.5 -> 3 | T25: =$A$25+0.5 -> 3 | U25: =$A$25+0.5 -> 3 | V25: =$A$25+0.5 -> 3 | ... Z25: =$A$25+0.5 -> 3 | AA25: =$A$25+1 -> 3.5 | AB25: =$A$25+1 -> 3.5 | AC25: =$A$25+1 -> 3.5 | AD25: =$A$25+1 -> 3.5 | AE25: =$A$25+1 -> 3.5 | AF25: =$A$25+1 -> 3.5 | AG25: =$A$25+1 -> 3.5 | AH25: =$A$25+1 -> 3.5 | ... AL25: =$A$25+1 -> 3.5
A26: 3 | B26: Стоимость доставки | C26: =$A$26 -> 3 | D26: =$A$26 -> 3 | E26: =$A$26 -> 3 | F26: =$A$26 -> 3 | G26: =$A$26 -> 3 | H26: =$A$26 -> 3 | I26: =$A$26 -> 3 | J26: =$A$26 -> 3 | ... N26: =$A$26 -> 3 | O26: =$A$26+0.5 -> 3.5 | P26: =$A$26+0.5 -> 3.5 | Q26: =$A$26+0.5 -> 3.5 | R26: =$A$26+0.5 -> 3.5 | S26: =$A$26+0.5 -> 3.5 | T26: =$A$26+0.5 -> 3.5 | U26: =$A$26+0.5 -> 3.5 | V26: =$A$26+0.5 -> 3.5 | ... Z26: =$A$26+0.5 -> 3.5 | AA26: =$A$26+1 -> 4 | AB26: =$A$26+1 -> 4 | AC26: =$A$26+1 -> 4 | AD26: =$A$26+1 -> 4 | AE26: =$A$26+1 -> 4 | AF26: =$A$26+1 -> 4 | AG26: =$A$26+1 -> 4 | AH26: =$A$26+1 -> 4 | ... AL26: =$A$26+1 -> 4
A27: 0.85 | B27: Скидки на 1 пользователя в месяц | C27: =$A$27 -> 0.85 | D27: =$A$27 -> 0.85 | E27: =D27-0.05 -> 0.8 | F27: =E27-0.05 -> 0.75 | G27: =F27-0.05 -> 0.7 | H27: =G27-0.05 -> 0.65 | I27: =H27-0.05 -> 0.6 | J27: =I27-0.05 -> 0.55 | K27: =J27-0.05 -> 0.5 | L27: =K27 -> 0.5 | M27: =L27 -> 0.5 | N27: =M27 -> 0.5 | O27: =N27 -> 0.5 | P27: =O27 -> 0.5 | Q27: =P27 -> 0.5 | R27: =Q27 -> 0.5 | S27: =R27 -> 0.5 | ... AL27: =AK27 -> 0.5
A28: 125 | B28: Бонусы на 1 курьера в месяц | C28: =$A$28 - (ROUND($C$29,0)-ROUND(C29,0))*10 -> 125 | D28: =$A$28 - (ROUND($C$29,0)-ROUND(D29,0))*10 -> 105 | E28: =$A$28 - (ROUND($C$29,0)-ROUND(E29,0))*10 -> 95 | F28: =$A$28 - (ROUND($C$29,0)-ROUND(F29,0))*10 -> 85 | G28: =$A$28 - (ROUND($C$29,0)-ROUND(G29,0))*10 -> 75 | H28: =$A$28 - (ROUND($C$29,0)-ROUND(H29,0))*10 -> 65 | I28: =$A$28 - (ROUND($C$29,0)-ROUND(I29,0))*10 -> 65 | J28: =$A$28 - (ROUND($C$29,0)-ROUND(J29,0))*10 -> 65 | ... AL28: =$A$28 - (ROUND($C$29,0)-ROUND(AL29,0))*10 -> 75
B29: Заказы в день на курьера | C29: =(C20/C30)/31 -> 12.5077 | D29: =(D20/D30)/31 -> 11.392231 | E29: =(E20/E30)/31 -> 9.9311371 | F29: =(F20/F30)/31 -> 8.8063295 | G29: =(G20/G30)/31 -> 7.9097053 | H29: =(H20/H30)/31 -> 7.1714407 | I29: =(I20/I30)/31 -> 6.5461456 | J29: =(J20/J30)/31 -> 6.6044535 | ... AL29: =(AL20/AL30)/31 -> 7.8571654
A30: 95 | B30: Кол-во курьеров | C30: =A30 -> 95 | D30: =C30*103% -> 97.85 | E30: =D30*110% -> 107.635 | F30: =E30*110% -> 118.3985 | G30: =F30*110% -> 130.23835 | H30: =G30*110% -> 143.26219 | I30: =H30*110% -> 157.5884 | J30: =I30 -> 157.5884 | K30: =J30 -> 157.5884 | L30: =K30 -> 157.5884 | M30: =L30 -> 157.5884 | N30: =M30 -> 157.5884 | O30: =N30 -> 157.5884 | P30: =O30 -> 157.5884 | Q30: =P30 -> 157.5884 | ... T30: =S30 -> 157.5884 | U30: =T30*102% -> 160.74017 | V30: =U30*102% -> 163.95498 | W30: =V30*102% -> 167.23407 | X30: =W30*102% -> 170.57876 | Y30: =X30*102% -> 173.99033 | Z30: =Y30*102% -> 177.47014 | AA30: =Z30*102% -> 181.01954 | AB30: =AA30*102% -> 184.63993 | ... AL30: =AK30*102% -> 225.07505
A31: 8 | B31: Кол-во сотрудников | C31: =$A$31 -> 8 | D31: =$A$31 -> 8 | E31: =$A$31 -> 8 | F31: =$A$31 -> 8 | G31: =$A$31 -> 8 | H31: =$A$31 -> 8 | I31: =$A$31 -> 8 | J31: =$A$31 -> 8 | K31: =$A$31 -> 8 | L31: =$A$31+1 -> 9 | M31: =$A$31+1 -> 9 | N31: =$A$31+1 -> 9 | O31: =$A$31+1 -> 9 | P31: =$A$31+1 -> 9 | Q31: =$A$31+2 -> 10 | R31: =$A$31+2 -> 10 | S31: =$A$31+2 -> 10 | T31: =$A$31+2 -> 10 | U31: =$A$31+2 -> 10 | V31: =$A$31+2 -> 10 | W31: =$A$31+2 -> 10 | X31: =$A$31+3 -> 11 | Y31: =$A$31+3 -> 11 | Z31: =$A$31+3 -> 11 | AA31: =$A$31+3 -> 11 | AB31: =$A$31+3 -> 11 | AC31: =$A$31+3 -> 11 | AD31: =$A$31+3 -> 11 | AE31: =$A$31+4 -> 12 | AF31: =$A$31+4 -> 12 | AG31: =$A$31+4 -> 12 | AH31: =$A$31+4 -> 12 | AI31: =$A$31+4 -> 12 | AJ31: =$A$31+4 -> 12 | AK31: =$A$31+4 -> 12 | AL31: =$A$31+4 -> 12
A32: 7.5 | B32: CAC | C32: =$A$32 -> 7.5 | D32: =$A$32 -> 7.5 | E32: =$A$32 -> 7.5 | F32: =$A$32 -> 7.5 | G32: =$A$32 -> 7.5 | H32: =$A$32 -> 7.5 | I32: =$A$32 -> 7.5 | J32: =$A$32 -> 7.5 | ... N32: =$A$32 -> 7.5 | O32: =$A$32*105% -> 7.875 | P32: =$A$32*105% -> 7.875 | Q32: =$A$32*105% -> 7.875 | R32: =$A$32*105% -> 7.875 | S32: =$A$32*105% -> 7.875 | T32: =$A$32*105% -> 7.875 | U32: =$A$32*105% -> 7.875 | V32: =$A$32*105% -> 7.875 | ... Z32: =$A$32*105% -> 7.875 | AA32: =$A$32*112% -> 8.4 | AB32: =$A$32*112% -> 8.4 | AC32: =$A$32*112% -> 8.4 | AD32: =$A$32*112% -> 8.4 | AE32: =$A$32*112% -> 8.4 | AF32: =$A$32*112% -> 8.4 | AG32: =$A$32*112% -> 8.4 | AH32: =$A$32*112% -> 8.4 | ... AL32: =$A$32*112% -> 8.4
B34: Расходы | C34: =SUM(C35:C40) -> 191487.58 | D34: =SUM(D35:D40) -> 184384.05 | E34: =SUM(E35:E40) -> 180241.34 | F34: =SUM(F35:F40) -> 177708.49 | G34: =SUM(G35:G40) -> 176238.46 | H34: =SUM(H35:H40) -> 175442.03 | I34: =SUM(I35:I40) -> 176613.84 | J34: =SUM(J35:J40) -> 177260.82 | ... AL34: =SUM(AL35:AL40) -> 304946.64
A35: 5300 | B35: Аренда | C35: =$A$35 -> 5300 | D35: =$A$35 -> 5300 | E35: =$A$35 -> 5300 | F35: =$A$35 -> 5300 | G35: =$A$35 -> 5300 | H35: =$A$35 -> 5300 | I35: =$A$35 -> 5300 | J35: =$A$35 -> 5300 | ... N35: =$A$35 -> 5300 | O35: =$A$35*110% -> 5830 | P35: =$A$35*110% -> 5830 | Q35: =$A$35*110% -> 5830 | R35: =$A$35*110% -> 5830 | S35: =$A$35*110% -> 5830 | T35: =$A$35*110% -> 5830 | U35: =$A$35*110% -> 5830 | V35: =$A$35*110% -> 5830 | ... Z35: =$A$35*110% -> 5830 | AA35: =$A$35*115% -> 6095 | AB35: =$A$35*115% -> 6095 | AC35: =$A$35*115% -> 6095 | AD35: =$A$35*115% -> 6095 | AE35: =$A$35*115% -> 6095 | AF35: =$A$35*115% -> 6095 | AG35: =$A$35*115% -> 6095 | AH35: =$A$35*115% -> 6095 | ... AL35: =$A$35*115% -> 6095
A36: 4000 | B36: ФОТ | C36: =$A$36*C31 -> 32000 | D36: =$A$36*D31 -> 32000 | E36: =$A$36*E31 -> 32000 | F36: =$A$36*F31 -> 32000 | G36: =$A$36*G31 -> 32000 | H36: =$A$36*H31 -> 32000 | I36: =$A$36*I31 -> 32000 | J36: =$A$36*J31 -> 32000 | ... N36: =$A$36*N31 -> 36000 | O36: =$A$36*O31*105% -> 37800 | P36: =$A$36*P31*105% -> 37800 | Q36: =$A$36*Q31*105% -> 42000 | R36: =$A$36*R31*105% -> 42000 | S36: =$A$36*S31*105% -> 42000 | T36: =$A$36*T31*105% -> 42000 | U36: =$A$36*U31*105% -> 42000 | V36: =$A$36*V31*105% -> 42000 | ... Z36: =$A$36*Z31*105% -> 46200 | AA36: =$A$36*AA31*110% -> 48400 | AB36: =$A$36*AB31*110% -> 48400 | AC36: =$A$36*AC31*110% -> 48400 | AD36: =$A$36*AD31*110% -> 48400 | AE36: =$A$36*AE31*110% -> 52800 | AF36: =$A$36*AF31*110% -> 52800 | AG36: =$A$36*AG31*110% -> 52800 | AH36: =$A$36*AH31*110% -> 52800 | ... AL36: =$A$36*AL31*110% -> 52800
B37: Бюджет на маркетинг | C37: =C13*C32 -> 37500 | D37: =D13*D32 -> 38250 | E37: =E13*E32 -> 39015 | F37: =F13*F32 -> 39795.3 | G37: =G13*G32 -> 40591.206 | H37: =H13*H32 -> 41403.03 | I37: =I13*I32 -> 42231.091 | J37: =J13*J32 -> 43075.713 | ... AL37: =AL13*AL32 -> 83995.361
B38: Затраты на скидки | C38: =C12*C27 -> 18203.43 | D38: =D12*D27 -> 17077.401 | E38: =E12*E27 -> 15412.594 | F38: =F12*F27 -> 14094.045 | G38: =G12*G27 -> 12996.622 | H38: =H12*H27 -> 12036.067 | I38: =I12*I27 -> 11155.638 | J38: =J12*J27 -> 10317.087 | ... AL38: =AL12*AL27 -> 15936.63
A39: 2.25 | B39: Выплаты курьерам за доставку | C39: =C20*$A$39 + C28*C30 -> 94754.146 | D39: =D20*$A$39 + D28*D30 -> 88026.652 | E39: =E20*$A$39 + E28*E30 -> 84783.747 | F39: =F20*$A$39 + F28*F30 -> 82789.142 | G39: =G20*$A$39 + G28*G30 -> 81620.627 | H39: =H20*$A$39 + H28*H30 -> 80972.931 | I39: =I20*$A$39 + I28*I30 -> 82197.112 | J39: =J20*$A$39 + J28*J30 -> 82838.02 | ... AL39: =AL20*$A$39 + AL28*AL30 -> 140230.15
B40: Прочие операционные расходы | C40: =SUM(C35:C36)*10% -> 3730 | D40: =SUM(D35:D36)*10% -> 3730 | E40: =SUM(E35:E36)*10% -> 3730 | F40: =SUM(F35:F36)*10% -> 3730 | G40: =SUM(G35:G36)*10% -> 3730 | H40: =SUM(H35:H36)*10% -> 3730 | I40: =SUM(I35:I36)*10% -> 3730 | J40: =SUM(J35:J36)*10% -> 3730 | ... AL40: =SUM(AL35:AL36)*10% -> 5889.5
B41: Прирост расходов (% к прошлому месяцу) | C41: 1 | D41: =(D34/C34)-100% -> -0.037096521 | E41: =(E34/D34)-100% -> -0.022467849 | F41: =(F34/E34)-100% -> -0.014052565 | G41: =(G34/F34)-100% -> -0.008272153 | H41: =(H34/G34)-100% -> -0.0045190302 | I41: =(I34/H34)-100% -> 0.0066791986 | J41: =(J34/I34)-100% -> 0.0036632378 | K41: =(K34/J34)-100% -> 0.0052587584 | ... AL41: =(AL34/AK34)-100% -> 0.015684313
B43: EBITDA (операционная прибыль) | C43: =C8-C34 -> 2614.9556 | D43: =D8-D34 -> -2288.3291 | E43: =E8-E34 -> -5625.9022 | F43: =F8-F34 -> -7386.2807 | G43: =G8-G34 -> -7959.6831 | H43: =H8-H34 -> -7612.5956 | I43: =I8-I34 -> -8098.2595 | J43: =J8-J34 -> -7244.2346 | ... AL43: =AL8-AL34 -> 73264.021
B44: EBITDA нарастающим итогом | C44: =C43 -> 2614.9556 | D44: =D43+C44 -> 326.62655 | E44: =E43+D44 -> -5299.2757 | F44: =F43+E44 -> -12685.556 | G44: =G43+F44 -> -20645.239 | H44: =H43+G44 -> -28257.835 | I44: =I43+H44 -> -36356.095 | J44: =J43+I44 -> -43600.329 | K44: =K43+J44 -> -49684.92 | ... AL44: =AL43+AK44 -> 858888.23
B45: Рентабельность EBITDA (% от общей выручки) | C45: =C43/C8 -> 0.013472033 | D45: =D43/D8 -> -0.012566627 | E45: =E43/E8 -> -0.032218813 | F45: =F43/F8 -> -0.043366516 | G45: =G43/G8 -> -0.047300578 | H45: =H43/H8 -> -0.045359121 | I45: =I43/I8 -> -0.048056444 | J45: =J43/J8 -> -0.042608988 | ... AL45: =AL43/AL8 -> 0.19371221
...

Sheet Финмодель сценарий 1
B1: Сценарий 1: Умеренный | C1: Небольшое снижение количества клиентов и рост стоимости привлечения, небольшое увеличение бонусов и скидок
B2: ОПиУ 2026-28 | C2: 2026 | O2: 2027 | AA2: 2028 | AM2: 2029
B3: Название статьи | C3: Январь | D3: Февраль | E3: Март | F3: Апрель | G3: Май | H3: Июнь | I3: Июль | J3: Август | K3: Сентябрь | L3: Октябрь | M3: Ноябрь | N3: Декабрь | O3: Январь | P3: Февраль | Q3: Март | R3: Апрель | S3: Май | T3: Июнь | U3: Июль | V3: Август | W3: Сентябрь | X3: Октябрь | Y3: Ноябрь | Z3: Декабрь | AA3: Январь | AB3: Февраль | AC3: Март | AD3: Апрель | AE3: Май | AF3: Июнь | AG3: Июль | AH3: Август | AI3: Сентябрь | AJ3: Октябрь | AK3: Ноябрь | AL3: Декабрь | AM3: Январь | AN3: Февраль | AO3: Март | AP3: Апрель | AQ3: Май | AR3: Июнь | AS3: Июль | AT3: Август | AU3: Сентябрь | AV3: Октябрь | AW3: Ноябрь | AX3: Декабрь
A5: 1.03 | B5: Выручка от реализации
A6: 3900 | B6: Выручка от комиссии | C6: =C21*C24*C25 -> 28769.325 | D6: =D21*D24*D25 -> 25717.604 | E6: =E21*E24*E25 -> 23801.795 | F6: =F21*F24*F25 -> 22649.623 | G6: =G21*G24*G25 -> 22011.715 | H6: =H21*H24*H25 -> 21721.047 | I6: =I21*I24*I25 -> 21665.763 | J6: =J21*J24*J25 -> 21770.976 | ... AX6: =AX21*AX24*AX25 -> 49430.489
B7: Выручка от подписки | C7: =C13*C26 -> 51244.95 | D7: =D13*D26 -> 45809.117 | E7: =E13*E26 -> 42396.608 | F7: =F13*F26 -> 40344.317 | G7: =G13*G26 -> 39208.054 | H7: =H13*H26 -> 38690.306 | I7: =I13*I26 -> 38591.832 | J7: =J13*J26 -> 38779.241 | ... AX7: =AX13*AX26 -> 116418.17
B8: Выручка от доставки | C8: =C21*C27 -> 105769.58 | D8: =D21*D27 -> 94550.016 | E8: =E21*E27 -> 87506.599 | F8: =F21*F27 -> 83270.671 | G8: =G21*G27 -> 80925.424 | H8: =H21*H27 -> 79856.791 | I8: =I21*I27 -> 79653.541 | J8: =J21*J27 -> 80040.354 | ... AX8: =AX21*AX27 -> 228844.86
B9: Общая выручка | C9: =SUM(C6:C8) -> 185783.85 | D9: =SUM(D6:D8) -> 166076.74 | E9: =SUM(E6:E8) -> 153705 | F9: =SUM(F6:F8) -> 146264.61 | G9: =SUM(G6:G8) -> 142145.19 | H9: =SUM(H6:H8) -> 140268.14 | I9: =SUM(I6:I8) -> 139911.14 | J9: =SUM(J6:J8) -> 140590.57 | ... AX9: =SUM(AX6:AX8) -> 394693.51
B10: Прирост выручки (% к прошлому месяцу) | C10: 1 | D10: =(D9/C9*100%)-100% -> -0.1060755 | E10: =(E9/D9*100%)-100% -> -0.07449409 | F10: =(F9/E9*100%)-100% -> -0.048406954 | G10: =(G9/F9*100%)-100% -> -0.028164138 | H10: =(H9/G9*100%)-100% -> -0.013205168 | I10: =(I9/H9*100%)-100% -> -0.0025451752 | J10: =(J9/I9*100%)-100% -> 0.004856189 | K10: =(K9/J9*100%)-100% -> 0.0099026811 | ... AX10: =(AX9/AW9*100%)-100% -> 0.019999999
B12: Воронка продаж
A13: 0.02 | B13: Активная база клиентов | C13: =30594-30594*C15 -> 20497.98 | D13: =C13+D14-(C13*D15) -> 18323.647 | E13: =D13+E14-(D13*E15) -> 16958.643 | F13: =E13+F14-(E13*F15) -> 16137.727 | G13: =F13+G14-(F13*G15) -> 15683.222 | H13: =G13+H14-(G13*H15) -> 15476.122 | I13: =H13+I14-(H13*I15) -> 15436.733 | J13: =I13+J14-(I13*J15) -> 15511.696 | K13: =J13+K14-(J13*K15) -> 15665.304 | ... AX13: =AW13+AX14-(AW13*AX15) -> 33262.334
A14: 4500 | B14: Новые клиенты | C14: =$A$14 -> 4500 | D14: =C14+C14*$A$13 -> 4590 | E14: =D14+D14*$A$13 -> 4681.8 | F14: =E14+E14*$A$13 -> 4775.436 | G14: =F14+F14*$A$13 -> 4870.9447 | H14: =G14+G14*$A$13 -> 4968.3636 | I14: =H14+H14*$A$13 -> 5067.7309 | J14: =I14+I14*$A$13 -> 5169.0855 | K14: =J14+J14*$A$13 -> 5272.4672 | ... AX14: =AW14+AW14*$A$13 -> 11413.546
A15: 0.33 | B15: Отток | C15: =$A$15 -> 0.33 | D15: =$A$15 -> 0.33 | E15: =$A$15 -> 0.33 | F15: =$A$15 -> 0.33 | G15: =$A$15 -> 0.33 | H15: =$A$15 -> 0.33 | I15: =$A$15 -> 0.33 | J15: =$A$15 -> 0.33 | ... AX15: =$A$15 -> 0.33
A16: 495 | B16: База шеф-поваров | C16: =$A$16 -> 495 | D16: =C16+(D14/18)-(C16*15%) -> 675.75 | E16: =D16+(E14/18)-(D16*15%) -> 834.4875 | F16: =E16+(F14/18)-(E16*15%) -> 974.61638 | G16: =F16+(G14/18)-(F16*15%) -> 1099.032 | H16: =G16+(H14/18)-(G16*15%) -> 1210.1974 | I16: =H16+(I14/18)-(H16*15%) -> 1310.2084 | J16: =I16+(J14/18)-(I16*15%) -> 1400.8485 | K16: =J16+(K14/18)-(J16*15%) -> 1483.6361 | ... AX16: =AW16+(AX14/18)-(AW16*15%) -> 3804.0313
B17: Заказчиков на одного повара | C17: =C13/C16 -> 41.410061 | D17: =D13/D16 -> 27.116014 | E17: =E13/E16 -> 20.322226 | F17: =F13/F16 -> 16.55803 | G17: =G13/G16 -> 14.270033 | H17: =H13/H16 -> 12.788098 | I17: =I13/I16 -> 11.781891 | J17: =J13/J16 -> 11.073072 | ... AX17: =AX13/AX16 -> 8.7439696
A18: 0.86 | B18: Процент успешных доставок | C18: =$A$18 -> 0.86 | D18: =$A$18 -> 0.86 | E18: =$A$18 -> 0.86 | F18: =$A$18 -> 0.86 | G18: =$A$18 -> 0.86 | H18: =$A$18 -> 0.86 | I18: =$A$18 -> 0.86 | J18: =$A$18 -> 0.86 | ... AX18: =$A$18 -> 0.86
A19: 2 | B19: Частотность созданных заказов | C19: =$A$19+RANDBETWEEN(-0.4, 0.1) -> 2 | D19: =$A$19+RANDBETWEEN(-0.4, 0.1) -> 2 | E19: =$A$19+RANDBETWEEN(-0.4, 0.1) -> 2 | F19: =$A$19+RANDBETWEEN(-0.4, 0.1) -> 2 | G19: =$A$19+RANDBETWEEN(-0.4, 0.1) -> 2 | H19: =$A$19+RANDBETWEEN(-0.4, 0.1) -> 2 | I19: =$A$19+RANDBETWEEN(-0.4, 0.1) -> 2 | J19: =$A$19+RANDBETWEEN(-0.4, 0.1) -> 2 | ... AX19: =$A$19+RANDBETWEEN(-0.4, 0.1) -> 2
B20: Созданные заказы | C20: =C13*C19 -> 40995.96 | D20: =D13*D19 -> 36647.293 | E20: =E13*E19 -> 33917.286 | F20: =F13*F19 -> 32275.454 | G20: =G13*G19 -> 31366.444 | H20: =H13*H19 -> 30952.244 | I20: =I13*I19 -> 30873.466 | J20: =J13*J19 -> 31023.393 | ... AX20: =AX13*AX19 -> 66524.667
B21: Выполненные заказы | C21: =C20*C18 -> 35256.526 | D21: =D20*D18 -> 31516.672 | E21: =E20*E18 -> 29168.866 | F21: =F20*F18 -> 27756.89 | G21: =G20*G18 -> 26975.141 | H21: =H20*H18 -> 26618.93 | I21: =I20*I18 -> 26551.18 | J21: =J20*J18 -> 26680.118 | ... AX21: =AX20*AX18 -> 57211.214
B23: Юнит-экономика
A24: 6.8 | B24: Средняя стоимость обеда | C24: =$A$24 -> 6.8 | D24: =$A$24 -> 6.8 | E24: =$A$24 -> 6.8 | F24: =$A$24 -> 6.8 | G24: =$A$24 -> 6.8 | H24: =$A$24 -> 6.8 | I24: =$A$24 -> 6.8 | J24: =$A$24 -> 6.8 | ... N24: =$A$24 -> 6.8 | O24: =$A$24+0.2 -> 7 | P24: =$A$24+0.2 -> 7 | Q24: =$A$24+0.2 -> 7 | R24: =$A$24+0.2 -> 7 | S24: =$A$24+0.2 -> 7 | T24: =$A$24+0.2 -> 7 | U24: =$A$24+0.2 -> 7 | V24: =$A$24+0.2 -> 7 | ... Z24: =$A$24+0.2 -> 7 | AA24: =$A$24+0.4 -> 7.2 | AB24: =$A$24+0.4 -> 7.2 | AC24: =$A$24+0.4 -> 7.2 | AD24: =$A$24+0.4 -> 7.2 | AE24: =$A$24+0.4 -> 7.2 | AF24: =$A$24+0.4 -> 7.2 | AG24: =$A$24+0.4 -> 7.2 | AH24: =$A$24+0.4 -> 7.2 | ... AX24: =$A$24+0.4 -> 7.2
A25: 0.12 | B25: Комиссия сервиса с шефов | C25: =$A$25 -> 0.12 | D25: =$A$25 -> 0.12 | E25: =$A$25 -> 0.12 | F25: =$A$25 -> 0.12 | G25: =$A$25 -> 0.12 | H25: =$A$25 -> 0.12 | I25: =$A$25 -> 0.12 | J25: =$A$25 -> 0.12 | ... AX25: =$A$25 -> 0.12
A26: 2.5 | B26: Стоимость подписки на сервис | C26: =$A$26 -> 2.5 | D26: =$A$26 -> 2.5 | E26: =$A$26 -> 2.5 | F26: =$A$26 -> 2.5 | G26: =$A$26 -> 2.5 | H26: =$A$26 -> 2.5 | I26: =$A$26 -> 2.5 | J26: =$A$26 -> 2.5 | ... N26: =$A$26 -> 2.5 | O26: =$A$26+0.5 -> 3 | P26: =$A$26+0.5 -> 3 | Q26: =$A$26+0.5 -> 3 | R26: =$A$26+0.5 -> 3 | S26: =$A$26+0.5 -> 3 | T26: =$A$26+0.5 -> 3 | U26: =$A$26+0.5 -> 3 | V26: =$A$26+0.5 -> 3 | ... Z26: =$A$26+0.5 -> 3 | AA26: =$A$26+1 -> 3.5 | AB26: =$A$26+1 -> 3.5 | AC26: =$A$26+1 -> 3.5 | AD26: =$A$26+1 -> 3.5 | AE26: =$A$26+1 -> 3.5 | AF26: =$A$26+1 -> 3.5 | AG26: =$A$26+1 -> 3.5 | AH26: =$A$26+1 -> 3.5 | ... AX26: =$A$26+1 -> 3.5
A27: 3 | B27: Стоимость доставки | C27: =$A$27 -> 3 | D27: =$A$27 -> 3 | E27: =$A$27 -> 3 | F27: =$A$27 -> 3 | G27: =$A$27 -> 3 | H27: =$A$27 -> 3 | I27: =$A$27 -> 3 | J27: =$A$27 -> 3 | ... N27: =$A$27 -> 3 | O27: =$A$27+0.5 -> 3.5 | P27: =$A$27+0.5 -> 3.5 | Q27: =$A$27+0.5 -> 3.5 | R27: =$A$27+0.5 -> 3.5 | S27: =$A$27+0.5 -> 3.5 | T27: =$A$27+0.5 -> 3.5 | U27: =$A$27+0.5 -> 3.5 | V27: =$A$27+0.5 -> 3.5 | ... Z27: =$A$27+0.5 -> 3.5 | AA27: =$A$27+1 -> 4 | AB27: =$A$27+1 -> 4 | AC27: =$A$27+1 -> 4 | AD27: =$A$27+1 -> 4 | AE27: =$A$27+1 -> 4 | AF27: =$A$27+1 -> 4 | AG27: =$A$27+1 -> 4 | AH27: =$A$27+1 -> 4 | ... AX27: =$A$27+1 -> 4
A28: 0.95 | B28: Скидки на 1 пользователя в месяц | C28: =$A$28 -> 0.95 | D28: =$A$28 -> 0.95 | E28: =D28-0.05 -> 0.9 | F28: =E28-0.05 -> 0.85 | G28: =F28-0.05 -> 0.8 | H28: =G28-0.05 -> 0.75 | I28: =H28-0.05 -> 0.7 | J28: =I28-0.05 -> 0.65 | K28: =J28-0.05 -> 0.6 | L28: =K28 -> 0.6 | M28: =L28 -> 0.6 | N28: =M28 -> 0.6 | O28: =N28 -> 0.6 | P28: =O28 -> 0.6 | Q28: =P28 -> 0.6 | R28: =Q28 -> 0.6 | S28: =R28 -> 0.6 | ... AX28: =AW28 -> 0.6
A29: 150 | B29: Бонусы на 1 курьера в месяц | C29: =$A$29 - (ROUND($C$30,0)-ROUND(C30,0))*10 -> 150 | D29: =$A$29 - (ROUND($C$30,0)-ROUND(D30,0))*10 -> 130 | E29: =$A$29 - (ROUND($C$30,0)-ROUND(E30,0))*10 -> 120 | F29: =$A$29 - (ROUND($C$30,0)-ROUND(F30,0))*10 -> 110 | G29: =$A$29 - (ROUND($C$30,0)-ROUND(G30,0))*10 -> 100 | H29: =$A$29 - (ROUND($C$30,0)-ROUND(H30,0))*10 -> 90 | I29: =$A$29 - (ROUND($C$30,0)-ROUND(I30,0))*10 -> 80 | J29: =$A$29 - (ROUND($C$30,0)-ROUND(J30,0))*10 -> 80 | ... AX29: =$A$29 - (ROUND($C$30,0)-ROUND(AX30,0))*10 -> 90
B30: Заказы в день на курьера | C30: =(C21/C31)/31 -> 11.971656 | D30: =(D21/D31)/31 -> 10.390055 | E30: =(E21/E31)/31 -> 8.74187 | F30: =(F21/F31)/31 -> 7.562457 | G30: =(G21/G31)/31 -> 6.6813335 | H30: =(H21/H31)/31 -> 5.9937322 | I30: =(I21/I31)/31 -> 5.4349792 | J30: =(J21/J31)/31 -> 5.4613724 | ... AX30: =(AX21/AX31)/31 -> 6.4653205
A31: 95 | B31: Кол-во курьеров | C31: =A31 -> 95 | D31: =C31*103% -> 97.85 | E31: =D31*110% -> 107.635 | F31: =E31*110% -> 118.3985 | G31: =F31*110% -> 130.23835 | H31: =G31*110% -> 143.26219 | I31: =H31*110% -> 157.5884 | J31: =I31 -> 157.5884 | K31: =J31 -> 157.5884 | L31: =K31 -> 157.5884 | M31: =L31 -> 157.5884 | N31: =M31 -> 157.5884 | O31: =N31 -> 157.5884 | P31: =O31 -> 157.5884 | Q31: =P31 -> 157.5884 | ... T31: =S31 -> 157.5884 | U31: =T31*102% -> 160.74017 | V31: =U31*102% -> 163.95498 | W31: =V31*102% -> 167.23407 | X31: =W31*102% -> 170.57876 | Y31: =X31*102% -> 173.99033 | Z31: =Y31*102% -> 177.47014 | AA31: =Z31*102% -> 181.01954 | AB31: =AA31*102% -> 184.63993 | ... AX31: =AW31*102% -> 285.44958
A32: 8 | B32: Кол-во сотрудников | C32: =$A$32 -> 8 | D32: =$A$32 -> 8 | E32: =$A$32 -> 8 | F32: =$A$32 -> 8 | G32: =$A$32 -> 8 | H32: =$A$32 -> 8 | I32: =$A$32 -> 8 | J32: =$A$32 -> 8 | K32: =$A$32 -> 8 | L32: =$A$32+1 -> 9 | M32: =$A$32+1 -> 9 | N32: =$A$32+1 -> 9 | O32: =$A$32+1 -> 9 | P32: =$A$32+1 -> 9 | Q32: =$A$32+2 -> 10 | R32: =$A$32+2 -> 10 | S32: =$A$32+2 -> 10 | T32: =$A$32+2 -> 10 | U32: =$A$32+2 -> 10 | V32: =$A$32+2 -> 10 | W32: =$A$32+2 -> 10 | X32: =$A$32+3 -> 11 | Y32: =$A$32+3 -> 11 | Z32: =$A$32+3 -> 11 | AA32: =$A$32+3 -> 11 | AB32: =$A$32+3 -> 11 | AC32: =$A$32+3 -> 11 | AD32: =$A$32+3 -> 11 | AE32: =$A$32+4 -> 12 | AF32: =$A$32+4 -> 12 | AG32: =$A$32+4 -> 12 | AH32: =$A$32+4 -> 12 | AI32: =$A$32+4 -> 12 | AJ32: =$A$32+4 -> 12 | AK32: =$A$32+4 -> 12 | AL32: =$A$32+4 -> 12 | AM32: =$A$32+3 -> 11 | AN32: =$A$32+3 -> 11 | AO32: =$A$32+3 -> 11 | AP32: =$A$32+3 -> 11 | AQ32: =$A$32+4 -> 12 | AR32: =$A$32+4 -> 12 | AS32: =$A$32+4 -> 12 | AT32: =$A$32+4 -> 12 | AU32: =$A$32+4 -> 12 | AV32: =$A$32+4 -> 12 | AW32: =$A$32+4 -> 12 | AX32: =$A$32+4 -> 12
A33: 9 | B33: CAC | C33: =$A$33 -> 9 | D33: =$A$33 -> 9 | E33: =$A$33 -> 9 | F33: =$A$33 -> 9 | G33: =$A$33 -> 9 | H33: =$A$33 -> 9 | I33: =$A$33 -> 9 | J33: =$A$33 -> 9 | ... N33: =$A$33 -> 9 | O33: =$A$33*105% -> 9.45 | P33: =$A$33*105% -> 9.45 | Q33: =$A$33*105% -> 9.45 | R33: =$A$33*105% -> 9.45 | S33: =$A$33*105% -> 9.45 | T33: =$A$33*105% -> 9.45 | U33: =$A$33*105% -> 9.45 | V33: =$A$33*105% -> 9.45 | ... Z33: =$A$33*105% -> 9.45 | AA33: =$A$33*112% -> 10.08 | AB33: =$A$33*112% -> 10.08 | AC33: =$A$33*112% -> 10.08 | AD33: =$A$33*112% -> 10.08 | AE33: =$A$33*112% -> 10.08 | AF33: =$A$33*112% -> 10.08 | AG33: =$A$33*112% -> 10.08 | AH33: =$A$33*112% -> 10.08 | ... AX33: =$A$33*112% -> 10.08
B35: Расходы | C35: =SUM(C36:C41) -> 194580.26 | D35: =SUM(D36:D41) -> 183380.48 | E35: =SUM(E36:E41) -> 176975.13 | F35: =SUM(F36:F41) -> 173202.83 | G35: =SUM(G36:G41) -> 171132.98 | H35: =SUM(H36:H41) -> 170138.55 | I35: =SUM(I36:I41) -> 169792.52 | J35: =SUM(J36:J41) -> 170271.71 | ... AX35: =SUM(AX36:AX41) -> 354206.14
A36: 5300 | B36: Аренда | C36: =$A$36 -> 5300 | D36: =$A$36 -> 5300 | E36: =$A$36 -> 5300 | F36: =$A$36 -> 5300 | G36: =$A$36 -> 5300 | H36: =$A$36 -> 5300 | I36: =$A$36 -> 5300 | J36: =$A$36 -> 5300 | ... N36: =$A$36 -> 5300 | O36: =$A$36*110% -> 5830 | P36: =$A$36*110% -> 5830 | Q36: =$A$36*110% -> 5830 | R36: =$A$36*110% -> 5830 | S36: =$A$36*110% -> 5830 | T36: =$A$36*110% -> 5830 | U36: =$A$36*110% -> 5830 | V36: =$A$36*110% -> 5830 | ... Z36: =$A$36*110% -> 5830 | AA36: =$A$36*115% -> 6095 | AB36: =$A$36*115% -> 6095 | AC36: =$A$36*115% -> 6095 | AD36: =$A$36*115% -> 6095 | AE36: =$A$36*115% -> 6095 | AF36: =$A$36*115% -> 6095 | AG36: =$A$36*115% -> 6095 | AH36: =$A$36*115% -> 6095 | ... AX36: =$A$36*115% -> 6095
A37: 4000 | B37: ФОТ | C37: =$A$37*C32 -> 32000 | D37: =$A$37*D32 -> 32000 | E37: =$A$37*E32 -> 32000 | F37: =$A$37*F32 -> 32000 | G37: =$A$37*G32 -> 32000 | H37: =$A$37*H32 -> 32000 | I37: =$A$37*I32 -> 32000 | J37: =$A$37*J32 -> 32000 | ... N37: =$A$37*N32 -> 36000 | O37: =$A$37*O32*105% -> 37800 | P37: =$A$37*P32*105% -> 37800 | Q37: =$A$37*Q32*105% -> 42000 | R37: =$A$37*R32*105% -> 42000 | S37: =$A$37*S32*105% -> 42000 | T37: =$A$37*T32*105% -> 42000 | U37: =$A$37*U32*105% -> 42000 | V37: =$A$37*V32*105% -> 42000 | ... Z37: =$A$37*Z32*105% -> 46200 | AA37: =$A$37*AA32*110% -> 48400 | AB37: =$A$37*AB32*110% -> 48400 | AC37: =$A$37*AC32*110% -> 48400 | AD37: =$A$37*AD32*110% -> 48400 | AE37: =$A$37*AE32*110% -> 52800 | AF37: =$A$37*AF32*110% -> 52800 | AG37: =$A$37*AG32*110% -> 52800 | AH37: =$A$37*AH32*110% -> 52800 | ... AX37: =$A$37*AX32*110% -> 52800
B38: Бюджет на маркетинг | C38: =C14*C33 -> 40500 | D38: =D14*D33 -> 41310 | E38: =E14*E33 -> 42136.2 | F38: =F14*F33 -> 42978.924 | G38: =G14*G33 -> 43838.502 | H38: =H14*H33 -> 44715.273 | I38: =I14*I33 -> 45609.578 | J38: =J14*J33 -> 46521.77 | ... AX38: =AX14*AX33 -> 115048.54
B39: Затраты на скидки | C39: =C13*C28 -> 19473.081 | D39: =D13*D28 -> 17407.464 | E39: =E13*E28 -> 15262.779 | F39: =F13*F28 -> 13717.068 | G39: =G13*G28 -> 12546.577 | H39: =H13*H28 -> 11607.092 | I39: =I13*I28 -> 10805.713 | J39: =J13*J28 -> 10082.603 | ... AX39: =AX13*AX28 -> 19957.4
A40: 2.25 | B40: Выплаты курьерам за доставку | C40: =C21*$A$40 + C29*C31 -> 93577.183 | D40: =D21*$A$40 + D29*D31 -> 83633.012 | E40: =E21*$A$40 + E29*E31 -> 78546.149 | F40: =F21*$A$40 + F29*F31 -> 75476.838 | G40: =G21*$A$40 + G29*G31 -> 73717.903 | H40: =H21*$A$40 + H29*H31 -> 72786.19 | I40: =I21*$A$40 + I29*I31 -> 72347.228 | J40: =J21*$A$40 + J29*J31 -> 72637.338 | ... AX40: =AX21*$A$40 + AX29*AX31 -> 154415.69
B41: Прочие операционные расходы | C41: =SUM(C36:C37)*10% -> 3730 | D41: =SUM(D36:D37)*10% -> 3730 | E41: =SUM(E36:E37)*10% -> 3730 | F41: =SUM(F36:F37)*10% -> 3730 | G41: =SUM(G36:G37)*10% -> 3730 | H41: =SUM(H36:H37)*10% -> 3730 | I41: =SUM(I36:I37)*10% -> 3730 | J41: =SUM(J36:J37)*10% -> 3730 | ... AX41: =SUM(AX36:AX37)*10% -> 5889.5
B42: Прирост расходов (% к прошлому месяцу) | C42: 1 | D42: =(D35/C35)-100% -> -0.0575587 | E42: =(E35/D35)-100% -> -0.034929282 | F42: =(F35/E35)-100% -> -0.021315413 | G42: =(G35/F35)-100% -> -0.011950423 | H42: =(H35/G35)-100% -> -0.0058108577 | I42: =(I35/H35)-100% -> -0.0020338411 | J42: =(J35/I35)-100% -> 0.0028222139 | K42: =(K35/J35)-100% -> 0.014197071 | ... AX42: =(AX35/AW35)-100% -> 0.016282427
B44: EBITDA (операционная прибыль) | C44: =C9-C35 -> -8796.4119 | D44: =D9-D35 -> -17303.739 | E44: =E9-E35 -> -23270.126 | F44: =F9-F35 -> -26938.219 | G44: =G9-G35 -> -28987.789 | H44: =H9-H35 -> -29870.411 | I44: =I9-I35 -> -29881.383 | J44: =J9-J35 -> -29681.139 | ... AX44: =AX9-AX35 -> 40487.376
B45: EBITDA нарастающим итогом | C45: =C44 -> -8796.4119 | D45: =D44+C45 -> -26100.151 | E45: =E44+D45 -> -49370.277 | F45: =F44+E45 -> -76308.496 | G45: =G44+F45 -> -105296.29 | H45: =H44+G45 -> -135166.7 | I45: =I44+H45 -> -165048.08 | J45: =J44+I45 -> -194729.22 | K45: =K44+J45 -> -225435.49 | ... AX45: =AX44+AW45 -> -12605.292
...

Sheet Финмодель сценарий 2
B1: Сценарий 2: Критический | C1: Значительное снижение количества клиентов и рост стоимости привлечения, вынужденное увеличение бонусов и скидок, снижение цен и комиссии
B2: ОПиУ 2026-28 | C2: 2026 | O2: 2027 | AA2: 2028
B3: Название статьи | C3: Январь | D3: Февраль | E3: Март | F3: Апрель | G3: Май | H3: Июнь | I3: Июль | J3: Август | K3: Сентябрь | L3: Октябрь | M3: Ноябрь | N3: Декабрь | O3: Январь | P3: Февраль | Q3: Март | R3: Апрель | S3: Май | T3: Июнь | U3: Июль | V3: Август | W3: Сентябрь | X3: Октябрь | Y3: Ноябрь | Z3: Декабрь | AA3: Январь | AB3: Февраль | AC3: Март | AD3: Апрель | AE3: Май | AF3: Июнь | AG3: Июль | AH3: Август | AI3: Сентябрь | AJ3: Октябрь | AK3: Ноябрь | AL3: Декабрь
A5: 1.03 | B5: Выручка от реализации
A6: 3900 | B6: Выручка от комиссии | C6: =C21*C24*C25 -> 15727.764 | D6: =D21*D24*D25 -> 12058.466 | E6: =E21*E24*E25 -> 9909.3238 | F6: =F21*F24*F25 -> 8673.3233 | G6: =G21*G24*G25 -> 7986.2776 | H6: =H21*H24*H25 -> 7629.6959 | I6: =I21*I24*I25 -> 7472.5054 | J6: =J21*J24*J25 -> 7436.0849 | ... AL6: =AL21*AL24*AL25 -> 13218.47
B7: Выручка от подписки | C7: =C13*C26 -> 36712.8 | D7: =D13*D26 -> 28147.68 | E7: =E13*E26 -> 23131.008 | F7: =F13*F26 -> 20245.853 | G7: =G13*G26 -> 18642.105 | H7: =H13*H26 -> 17809.748 | I7: =I13*I26 -> 17442.823 | J7: =J13*J26 -> 17357.808 | ... AL7: =AL13*AL26 -> 43711.872
B8: Выручка от доставки | C8: =C21*C27 -> 64247.4 | D8: =D21*D27 -> 49258.44 | E8: =E21*E27 -> 40479.264 | F8: =F21*F27 -> 35430.242 | G8: =G21*G27 -> 32623.683 | H8: =H21*H27 -> 31167.058 | I8: =I21*I27 -> 30524.94 | J8: =J21*J27 -> 30376.164 | ... AL8: =AL21*AL27 -> 71396.058
B9: Общая выручка | C9: =SUM(C6:C8) -> 116687.96 | D9: =SUM(D6:D8) -> 89464.586 | E9: =SUM(E6:E8) -> 73519.596 | F9: =SUM(F6:F8) -> 64349.419 | G9: =SUM(G6:G8) -> 59252.065 | H9: =SUM(H6:H8) -> 56606.502 | I9: =SUM(I6:I8) -> 55440.269 | J9: =SUM(J6:J8) -> 55170.056 | ... AL9: =SUM(AL6:AL8) -> 128326.4
B10: Прирост выручки (% к прошлому месяцу) | C10: 1 | D10: =(D9/C9*100%)-100% -> -0.23330065 | E10: =(E9/D9*100%)-100% -> -0.17822684 | F10: =(F9/E9*100%)-100% -> -0.12473106 | G10: =(G9/F9*100%)-100% -> -0.079213663 | H10: =(H9/G9*100%)-100% -> -0.044649306 | I10: =(I9/H9*100%)-100% -> -0.020602455 | J10: =(J9/I9*100%)-100% -> -0.0048739372 | K10: =(K9/J9*100%)-100% -> 0.005002541 | ... AL10: =(AL9/AK9*100%)-100% -> 0.019999991
B12: Воронка продаж
A13: 0.02 | B13: Активная база клиентов | C13: =30594-30594*C15 -> 18356.4 | D13: =C13+D14-(C13*D15) -> 14073.84 | E13: =D13+E14-(D13*E15) -> 11565.504 | F13: =E13+F14-(E13*F15) -> 10122.926 | G13: =F13+G14-(F13*G15) -> 9321.0523 | H13: =G13+H14-(G13*H15) -> 8904.8738 | I13: =H13+I14-(H13*I15) -> 8721.4115 | J13: =I13+J14-(I13*J15) -> 8678.9039 | K13: =J13+K14-(J13*K15) -> 8722.3205 | ... AL13: =AK13+AL14-(AK13*AL15) -> 14570.624
A14: 3000 | B14: Новые клиенты | C14: =$A$14 -> 3000 | D14: =C14+C14*$A$13 -> 3060 | E14: =D14+D14*$A$13 -> 3121.2 | F14: =E14+E14*$A$13 -> 3183.624 | G14: =F14+F14*$A$13 -> 3247.2965 | H14: =G14+G14*$A$13 -> 3312.2424 | I14: =H14+H14*$A$13 -> 3378.4873 | J14: =I14+I14*$A$13 -> 3446.057 | K14: =J14+J14*$A$13 -> 3514.9781 | ... AL14: =AK14+AK14*$A$13 -> 5999.6687
A15: 0.4 | B15: Отток | C15: =$A$15 -> 0.4 | D15: =$A$15 -> 0.4 | E15: =$A$15 -> 0.4 | F15: =$A$15 -> 0.4 | G15: =$A$15 -> 0.4 | H15: =$A$15 -> 0.4 | I15: =$A$15 -> 0.4 | J15: =$A$15 -> 0.4 | ... AL15: =$A$15 -> 0.4
A16: 495 | B16: База шеф-поваров | C16: =$A$16 -> 495 | D16: =C16+(D14/18)-(C16*15%) -> 590.75 | E16: =D16+(E14/18)-(D16*15%) -> 675.5375 | F16: =E16+(F14/18)-(E16*15%) -> 751.07488 | G16: =F16+(G14/18)-(F16*15%) -> 818.819 | H16: =G16+(H14/18)-(G16*15%) -> 880.00962 | I16: =H16+(I14/18)-(H16*15%) -> 935.70191 | J16: =I16+(J14/18)-(I16*15%) -> 986.79424 | K16: =J16+(K14/18)-(J16*15%) -> 1034.0517 | ... AL16: =AK16+(AL14/18)-(AK16*15%) -> 1998.1797
B17: Заказчиков на одного повара | C17: =C13/C16 -> 37.083636 | D17: =D13/D16 -> 23.823682 | E17: =E13/E16 -> 17.120447 | F17: =F13/F16 -> 13.477919 | G17: =G13/G16 -> 11.383532 | H17: =H13/H16 -> 10.119064 | I17: =I13/I16 -> 9.3207157 | J17: =J13/J16 -> 8.7950493 | ... AL17: =AL13/AL16 -> 7.2919487
A18: 0.7 | B18: Процент успешных доставок | C18: =$A$18 -> 0.7 | D18: =$A$18 -> 0.7 | E18: =$A$18 -> 0.7 | F18: =$A$18 -> 0.7 | G18: =$A$18 -> 0.7 | H18: =$A$18 -> 0.7 | I18: =$A$18 -> 0.7 | J18: =$A$18 -> 0.7 | ... AL18: =$A$18 -> 0.7
A19: 2 | B19: Частотность созданных заказов | C19: =$A$19+RANDBETWEEN(-0.4, 0.1) -> 2 | D19: =$A$19+RANDBETWEEN(-0.4, 0.1) -> 2 | E19: =$A$19+RANDBETWEEN(-0.4, 0.1) -> 2 | F19: =$A$19+RANDBETWEEN(-0.4, 0.1) -> 2 | G19: =$A$19+RANDBETWEEN(-0.4, 0.1) -> 2 | H19: =$A$19+RANDBETWEEN(-0.4, 0.1) -> 2 | I19: =$A$19+RANDBETWEEN(-0.4, 0.1) -> 2 | J19: =$A$19+RANDBETWEEN(-0.4, 0.1) -> 2 | ... AL19: =$A$19+RANDBETWEEN(-0.4, 0.1) -> 2
B20: Созданные заказы | C20: =C13*C19 -> 36712.8 | D20: =D13*D19 -> 28147.68 | E20: =E13*E19 -> 23131.008 | F20: =F13*F19 -> 20245.853 | G20: =G13*G19 -> 18642.105 | H20: =H13*H19 -> 17809.748 | I20: =I13*I19 -> 17442.823 | J20: =J13*J19 -> 17357.808 | ... AL20: =AL13*AL19 -> 29141.248
B21: Выполненные заказы | C21: =C20*C18 -> 25698.96 | D21: =D20*D18 -> 19703.376 | E21: =E20*E18 -> 16191.706 | F21: =F20*F18 -> 14172.097 | G21: =G20*G18 -> 13049.473 | H21: =H20*H18 -> 12466.823 | I21: =I20*I18 -> 12209.976 | J21: =J20*J18 -> 12150.465 | ... AL21: =AL20*AL18 -> 20398.874
B23: Юнит-экономика
A24: 6.8 | B24: Средняя стоимость обеда | C24: =$A$24 -> 6.8 | D24: =$A$24 -> 6.8 | E24: =$A$24 -> 6.8 | F24: =$A$24 -> 6.8 | G24: =$A$24 -> 6.8 | H24: =$A$24 -> 6.8 | I24: =$A$24 -> 6.8 | J24: =$A$24 -> 6.8 | ... N24: =$A$24 -> 6.8 | O24: =$A$24+0.2 -> 7 | P24: =$A$24+0.2 -> 7 | Q24: =$A$24+0.2 -> 7 | R24: =$A$24+0.2 -> 7 | S24: =$A$24+0.2 -> 7 | T24: =$A$24+0.2 -> 7 | U24: =$A$24+0.2 -> 7 | V24: =$A$24+0.2 -> 7 | ... Z24: =$A$24+0.2 -> 7 | AA24: =$A$24+0.4 -> 7.2 | AB24: =$A$24+0.4 -> 7.2 | AC24: =$A$24+0.4 -> 7.2 | AD24: =$A$24+0.4 -> 7.2 | AE24: =$A$24+0.4 -> 7.2 | AF24: =$A$24+0.4 -> 7.2 | AG24: =$A$24+0.4 -> 7.2 | AH24: =$A$24+0.4 -> 7.2 | ... AL24: =$A$24+0.4 -> 7.2
A25: 0.09 | B25: Комиссия сервиса с шефов | C25: =$A$25 -> 0.09 | D25: =$A$25 -> 0.09 | E25: =$A$25 -> 0.09 | F25: =$A$25 -> 0.09 | G25: =$A$25 -> 0.09 | H25: =$A$25 -> 0.09 | I25: =$A$25 -> 0.09 | J25: =$A$25 -> 0.09 | ... AL25: =$A$25 -> 0.09
A26: 2 | B26: Стоимость подписки на сервис | C26: =$A$26 -> 2 | D26: =$A$26 -> 2 | E26: =$A$26 -> 2 | F26: =$A$26 -> 2 | G26: =$A$26 -> 2 | H26: =$A$26 -> 2 | I26: =$A$26 -> 2 | J26: =$A$26 -> 2 | ... N26: =$A$26 -> 2 | O26: =$A$26+0.5 -> 2.5 | P26: =$A$26+0.5 -> 2.5 | Q26: =$A$26+0.5 -> 2.5 | R26: =$A$26+0.5 -> 2.5 | S26: =$A$26+0.5 -> 2.5 | T26: =$A$26+0.5 -> 2.5 | U26: =$A$26+0.5 -> 2.5 | V26: =$A$26+0.5 -> 2.5 | ... Z26: =$A$26+0.5 -> 2.5 | AA26: =$A$26+1 -> 3 | AB26: =$A$26+1 -> 3 | AC26: =$A$26+1 -> 3 | AD26: =$A$26+1 -> 3 | AE26: =$A$26+1 -> 3 | AF26: =$A$26+1 -> 3 | AG26: =$A$26+1 -> 3 | AH26: =$A$26+1 -> 3 | ... AL26: =$A$26+1 -> 3
A27: 2.5 | B27: Стоимость доставки | C27: =$A$27 -> 2.5 | D27: =$A$27 -> 2.5 | E27: =$A$27 -> 2.5 | F27: =$A$27 -> 2.5 | G27: =$A$27 -> 2.5 | H27: =$A$27 -> 2.5 | I27: =$A$27 -> 2.5 | J27: =$A$27 -> 2.5 | ... N27: =$A$27 -> 2.5 | O27: =$A$27+0.5 -> 3 | P27: =$A$27+0.5 -> 3 | Q27: =$A$27+0.5 -> 3 | R27: =$A$27+0.5 -> 3 | S27: =$A$27+0.5 -> 3 | T27: =$A$27+0.5 -> 3 | U27: =$A$27+0.5 -> 3 | V27: =$A$27+0.5 -> 3 | ... Z27: =$A$27+0.5 -> 3 | AA27: =$A$27+1 -> 3.5 | AB27: =$A$27+1 -> 3.5 | AC27: =$A$27+1 -> 3.5 | AD27: =$A$27+1 -> 3.5 | AE27: =$A$27+1 -> 3.5 | AF27: =$A$27+1 -> 3.5 | AG27: =$A$27+1 -> 3.5 | AH27: =$A$27+1 -> 3.5 | ... AL27: =$A$27+1 -> 3.5
A28: 1.5 | B28: Скидки на 1 пользователя в месяц | C28: =$A$28 -> 1.5 | D28: =$A$28 -> 1.5 | E28: =D28-0.05 -> 1.45 | F28: =E28-0.05 -> 1.4 | G28: =F28-0.05 -> 1.35 | H28: =G28-0.05 -> 1.3 | I28: =H28-0.05 -> 1.25 | J28: =I28-0.05 -> 1.2 | K28: =J28-0.05 -> 1.15 | L28: =K28 -> 1.15 | M28: =L28 -> 1.15 | N28: =M28 -> 1.15 | O28: =N28 -> 1.15 | P28: =O28 -> 1.15 | Q28: =P28 -> 1.15 | R28: =Q28 -> 1.15 | S28: =R28 -> 1.15 | ... AL28: =AK28 -> 1.15
A29: 200 | B29: Бонусы на 1 курьера в месяц | C29: =$A$29 - (ROUND($C$30,0)-ROUND(C30,0))*10 -> 200 | D29: =$A$29 - (ROUND($C$30,0)-ROUND(D30,0))*10 -> 170 | E29: =$A$29 - (ROUND($C$30,0)-ROUND(E30,0))*10 -> 160 | F29: =$A$29 - (ROUND($C$30,0)-ROUND(F30,0))*10 -> 150 | G29: =$A$29 - (ROUND($C$30,0)-ROUND(G30,0))*10 -> 140 | H29: =$A$29 - (ROUND($C$30,0)-ROUND(H30,0))*10 -> 140 | I29: =$A$29 - (ROUND($C$30,0)-ROUND(I30,0))*10 -> 130 | J29: =$A$29 - (ROUND($C$30,0)-ROUND(J30,0))*10 -> 130 | ... AL29: =$A$29 - (ROUND($C$30,0)-ROUND(AL30,0))*10 -> 140
B30: Заказы в день на курьера | C30: =(C21/C31)/31 -> 8.7263022 | D30: =(D21/D31)/31 -> 6.4955828 | E30: =(E21/E31)/31 -> 4.8526324 | F30: =(F21/F31)/31 -> 3.8612349 | G30: =(G21/G31)/31 -> 3.2321567 | H30: =(H21/H31)/31 -> 2.8071301 | I30: =(I21/I31)/31 -> 2.4993603 | J30: =(J21/J31)/31 -> 2.4871786 | ... AL30: =(AL21/AL31)/31 -> 2.9235946
A31: 95 | B31: Кол-во курьеров | C31: =A31 -> 95 | D31: =C31*103% -> 97.85 | E31: =D31*110% -> 107.635 | F31: =E31*110% -> 118.3985 | G31: =F31*110% -> 130.23835 | H31: =G31*110% -> 143.26219 | I31: =H31*110% -> 157.5884 | J31: =I31 -> 157.5884 | K31: =J31 -> 157.5884 | L31: =K31 -> 157.5884 | M31: =L31 -> 157.5884 | N31: =M31 -> 157.5884 | O31: =N31 -> 157.5884 | P31: =O31 -> 157.5884 | Q31: =P31 -> 157.5884 | ... T31: =S31 -> 157.5884 | U31: =T31*102% -> 160.74017 | V31: =U31*102% -> 163.95498 | W31: =V31*102% -> 167.23407 | X31: =W31*102% -> 170.57876 | Y31: =X31*102% -> 173.99033 | Z31: =Y31*102% -> 177.47014 | AA31: =Z31*102% -> 181.01954 | AB31: =AA31*102% -> 184.63993 | ... AL31: =AK31*102% -> 225.07505
A32: 8 | B32: Кол-во сотрудников | C32: =$A$32 -> 8 | D32: =$A$32 -> 8 | E32: =$A$32 -> 8 | F32: =$A$32 -> 8 | G32: =$A$32 -> 8 | H32: =$A$32 -> 8 | I32: =$A$32 -> 8 | J32: =$A$32 -> 8 | K32: =$A$32 -> 8 | L32: =$A$32+1 -> 9 | M32: =$A$32+1 -> 9 | N32: =$A$32+1 -> 9 | O32: =$A$32+1 -> 9 | P32: =$A$32+1 -> 9 | Q32: =$A$32+2 -> 10 | R32: =$A$32+2 -> 10 | S32: =$A$32+2 -> 10 | T32: =$A$32+2 -> 10 | U32: =$A$32+2 -> 10 | V32: =$A$32+2 -> 10 | W32: =$A$32+2 -> 10 | X32: =$A$32+3 -> 11 | Y32: =$A$32+3 -> 11 | Z32: =$A$32+3 -> 11 | AA32: =$A$32+3 -> 11 | AB32: =$A$32+3 -> 11 | AC32: =$A$32+3 -> 11 | AD32: =$A$32+3 -> 11 | AE32: =$A$32+4 -> 12 | AF32: =$A$32+4 -> 12 | AG32: =$A$32+4 -> 12 | AH32: =$A$32+4 -> 12 | AI32: =$A$32+4 -> 12 | AJ32: =$A$32+4 -> 12 | AK32: =$A$32+4 -> 12 | AL32: =$A$32+4 -> 12
A33: 14 | B33: CAC | C33: =$A$33 -> 14 | D33: =$A$33 -> 14 | E33: =$A$33 -> 14 | F33: =$A$33 -> 14 | G33: =$A$33 -> 14 | H33: =$A$33 -> 14 | I33: =$A$33 -> 14 | J33: =$A$33 -> 14 | ... N33: =$A$33 -> 14 | O33: =$A$33*105% -> 14.7 | P33: =$A$33*105% -> 14.7 | Q33: =$A$33*105% -> 14.7 | R33: =$A$33*105% -> 14.7 | S33: =$A$33*105% -> 14.7 | T33: =$A$33*105% -> 14.7 | U33: =$A$33*105% -> 14.7 | V33: =$A$33*105% -> 14.7 | ... Z33: =$A$33*105% -> 14.7 | AA33: =$A$33*112% -> 15.68 | AB33: =$A$33*112% -> 15.68 | AC33: =$A$33*112% -> 15.68 | AD33: =$A$33*112% -> 15.68 | AE33: =$A$33*112% -> 15.68 | AF33: =$A$33*112% -> 15.68 | AG33: =$A$33*112% -> 15.68 | AH33: =$A$33*112% -> 15.68 | ... AL33: =$A$33*112% -> 15.68
B35: Расходы | C35: =SUM(C36:C41) -> 187387.26 | D35: =SUM(D36:D41) -> 165947.86 | E35: =SUM(E36:E41) -> 155149.72 | F35: =SUM(F36:F41) -> 149419.83 | G35: =SUM(G36:G41) -> 146670.26 | H35: =SUM(H36:H41) -> 147084.79 | I35: =SUM(I36:I41) -> 147189.52 | J35: =SUM(J36:J41) -> 147514.52 | ... AL35: =SUM(AL36:AL41) -> 253023.49
A36: 5300 | B36: Аренда | C36: =$A$36 -> 5300 | D36: =$A$36 -> 5300 | E36: =$A$36 -> 5300 | F36: =$A$36 -> 5300 | G36: =$A$36 -> 5300 | H36: =$A$36 -> 5300 | I36: =$A$36 -> 5300 | J36: =$A$36 -> 5300 | ... N36: =$A$36 -> 5300 | O36: =$A$36*110% -> 5830 | P36: =$A$36*110% -> 5830 | Q36: =$A$36*110% -> 5830 | R36: =$A$36*110% -> 5830 | S36: =$A$36*110% -> 5830 | T36: =$A$36*110% -> 5830 | U36: =$A$36*110% -> 5830 | V36: =$A$36*110% -> 5830 | ... Z36: =$A$36*110% -> 5830 | AA36: =$A$36*115% -> 6095 | AB36: =$A$36*115% -> 6095 | AC36: =$A$36*115% -> 6095 | AD36: =$A$36*115% -> 6095 | AE36: =$A$36*115% -> 6095 | AF36: =$A$36*115% -> 6095 | AG36: =$A$36*115% -> 6095 | AH36: =$A$36*115% -> 6095 | ... AL36: =$A$36*115% -> 6095
